Workbook

Sheet ASX funds
A1: ASX monitoring-eligible funds
A2: 98 funds · as at 2026-08-31 · GREEN 12 · AMBER 67 · RED 19
A3: GREEN = every input present and the signal clears the uncertainty in our own NAV. A blank cell means we hold no value - never a zero. Rows whose NAV jumps implausibly from the fund's own previous figure are forced to RED here, overriding the audit, which predates that check.
A5: Ticker | B5: Fund | C5: Status | D5: Price | E5: Price age (d) | F5: NAV | G5: NAV date | H5: NAV source | I5: NAV age (d) | J5: NAV error | K5: Discount | L5: Avg discount 36m | M5: Z score | N5: Previous NAV | O5: NAV jump | P5: Why not green | Q5: What would fix it
A6: ARG | B6: Argo Investments Limited | C6: GREEN | D6: 9.3100004 | E6: 3 | F6: 10.94 | G6: 2026-08-24 | H6: Fund's own NTA announcement | I6: 5 | J6: 0.02411 | K6: -0.148994 | L6: -0.098194 | M6: -0.9731 | N6: 10.84 | O6: 0.0092250923
A7: AUI | B7: Australian United Investment Company Limited | C7: GREEN | D7: 11.69 | E7: 3 | F7: 14.25 | G7: 2026-08-21 | H7: Fund's own NTA announcement | I7: 6 | J7: 0.027773 | K7: -0.179649 | L7: -0.12923 | M7: -1.0687 | N7: 13.75 | O7: 0.036363636
A8: CAM | B8: Clime Capital Limited | C8: GREEN | D8: 0.685 | E8: 3 | F8: 0.825 | G8: 2026-08-19 | H8: Monthly report | I8: 8 | J8: 0.031298 | K8: -0.169697 | L8: -0.052216 | M8: -1.8772 | N8: 0.8225 | O8: 0.0030395137
A9: KAT | B9: Katana Capital Limited | C9: GREEN | D9: 1.38 | E9: 3 | F9: 1.442 | G9: 2026-07-31 | H9: Fund's own NTA announcement | I9: 21 | J9: 0.073726 | K9: -0.042996 | L9: -0.122083 | M9: 1.9119 | N9: 1.557 | O9: 0.073859987
A10: LSX | B10: Lion Selection Group Limited | C10: GREEN | D10: 0.95499998 | E10: 3 | F10: 0.967 | G10: 2026-07-31 | H10: Fund's own NTA announcement | I10: 21 | J10: 0.13892 | K10: -0.01241 | L10: -0.210529 | M10: 1.9756 | N10: 0.976 | O10: 0.0092213115
A11: MFF | B11: MFF Capital Investments Limited | C11: GREEN | D11: 5.4000001 | E11: 3 | F11: 5.213 | G11: 2026-08-17 | H11: Fund's own NTA announcement | I11: 10 | J11: 0.059102 | K11: 0.035872 | L11: -0.104498 | M11: 2.4072 | N11: 4.991 | O11: 0.044480064
A12: NSC | B12: Naos Small Cap Opportunities Company Limited | C12: GREEN | D12: 0.31999999 | E12: 3 | F12: 0.28 | G12: 2026-07-31 | H12: Fund's own NTA announcement | I12: 21 | J12: 0.111527 | K12: 0.142857 | L12: -0.07772 | M12: 2.1899 | N12: 0.28 | O12: 0
A13: RYD | B13: Ryder Capital Limited | C13: GREEN | D13: 2.1199999 | E13: 3 | F13: 2.024 | G13: 2026-08-10 | H13: Fund's own NTA announcement | I13: 15 | J13: 0.071471 | K13: 0.047431 | L13: -0.142399 | M13: 3.4352 | N13: 1.9803 | O13: 0.022067364
A14: SB2 | B14: Salter Brothers Emerging Companies Limited | C14: GREEN | D14: 0.6225 | E14: 3 | F14: 0.802 | G14: 2026-07-31 | H14: Fund's own NTA announcement | I14: 21 | J14: 0.038573 | K14: -0.223815 | L14: -0.335991 | M14: 1.6214 | N14: 0.815 | O14: 0.01595092
A15: SNC | B15: Sandon Capital Investments Limited | C15: GREEN | D15: 0.73000002 | E15: 3 | F15: 0.7439 | G15: 2026-07-31 | H15: Fund's own NTA announcement | I15: 21 | J15: 0.083673 | K15: -0.018685 | L15: -0.10989 | M15: 1.493 | N15: 0.7205 | O15: 0.032477446
A16: TVL | B16: Touch Ventures Limited | C16: GREEN | D16: 0.057 | E16: 3 | F16: 0.105 | G16: 2026-07-31 | H16: Fund's own NTA announcement | I16: 21 | J16: 0.062375 | K16: -0.457143 | L16: -0.311658 | M16: -0.2009 | N16: 0.108 | O16: 0.027777778
A17: WQG | B17: WCM Global Growth Limited | C17: GREEN | D17: 2.1400001 | E17: 3 | F17: 2.056 | G17: 2026-08-21 | H17: Fund's own NTA announcement | I17: 6 | J17: 0.041012 | K17: 0.040856 | L17: -0.103434 | M17: 3.1393 | N17: 2.178 | O17: 0.056014692
A18: DN1 | B18: Dominion Income Trust 1 | C18: AMBER | D18: 99.25 | E18: 3 | F18: 100.15 | G18: 2026-08-13 | H18: Monthly report | I18: 12 | J18: 0.03235 | K18: -0.008987 | N18: 102.72655 | O18: 0.025081607 | P18: Fewer than 24 months of discount history | Q18: the fund needs its own discount history in the monthly panel; until then it can be monitored but not z-scored
A19: GLS | B19: L1 Global Long Short Fund Limited | C19: AMBER | D19: 2.1199999 | E19: 3 | F19: 1.77 | G19: 2026-07-31 | H19: Fund's own NTA announcement | I19: 21 | J19: 0.091502 | K19: 0.19774 | N19: 1.722 | O19: 0.027874564 | P19: Fewer than 24 months of discount history | Q19: the fund needs its own discount history in the monthly panel; until then it can be monitored but not z-scored
A20: LF1 | B20: La Trobe Private Credit Fund | C20: AMBER | D20: 1.9 | E20: 3 | F20: 1.96 | G20: 2026-07-31 | H20: Fund's own NTA announcement | I20: 21 | J20: 0.048389 | K20: -0.030612 | N20: 1.97 | O20: 0.0050761421 | P20: Fewer than 24 months of discount history | Q20: the fund needs its own discount history in the monthly panel; until then it can be monitored but not z-scored
A21: LGF | B21: L1 Gold Fund Limited | C21: AMBER | D21: 2.3800001 | E21: 3 | F21: 1.7534 | G21: 2026-06-30 | H21: ASX monthly report | I21: 44 | J21: 0.153067 | K21: 0.357363 | N21: 1.8254 | O21: 0.03944341 | P21: Fewer than 24 months of discount history | Q21: the fund needs its own discount history in the monthly panel; until then it can be monitored but not z-scored
A22: MRE | B22: Metrics Real Estate Multi-Strategy Fund | C22: AMBER | D22: 1.77 | E22: 3 | F22: 2.5429 | G22: 2026-06-30 | H22: ASX monthly report | I22: 44 | J22: 0.061946 | K22: -0.303944 | N22: 2.4886 | O22: 0.021819497 | P22: Fewer than 24 months of discount history | Q22: the fund needs its own discount history in the monthly panel; until then it can be monitored but not z-scored
A23: RG1 | B23: Regal Partners Global Investments Limited | C23: AMBER | D23: 2.53 | E23: 3 | F23: 2.93 | G23: 2026-08-23 | H23: Fund's own NTA announcement | I23: 5 | J23: 0.044648 | K23: -0.136519 | N23: 2.65 | O23: 0.10566038 | P23: Fewer than 24 months of discount history | Q23: the fund needs its own discount history in the monthly panel; until then it can be monitored but not z-scored
A24: SET | B24: Solaris Australian Equity Income Plus Limited | C24: AMBER | D24: 2.1900001 | E24: 3 | F24: 2.037 | G24: 2026-08-27 | H24: Fund's earlier published NTA | I24: 2 | J24: 0.022752 | K24: 0.07511 | N24: 1.985 | O24: 0.026196474 | P24: Fewer than 24 months of discount history | Q24: the fund needs its own discount history in the monthly panel; until then it can be monitored but not z-scored
A25: UWC | B25: Underwood Capital Limited | C25: AMBER | D25: 0.057 | E25: 3 | F25: 0.1033 | G25: 2026-06-30 | H25: ASX monthly report | I25: 44 | J25: 0.153067 | K25: -0.448209 | N25: 0.1034 | O25: 0.00096711799 | P25: Fewer than 24 months of discount history | Q25: the fund needs its own discount history in the monthly panel; until then it can be monitored but not z-scored
A26: WHI | B26: Whitefield Income Limited | C26: AMBER | D26: 1.3 | E26: 3 | F26: 1.21 | G26: 2026-06-30 | H26: ASX monthly report | I26: 44 | J26: 0.106718 | K26: 0.07438 | N26: 1.22 | O26: 0.0081967213 | P26: Fewer than 24 months of discount history | Q26: the fund needs its own discount history in the monthly panel; until then it can be monitored but not z-scored
A27: WMX | B27: WAM Income Maximiser Limited | C27: AMBER | D27: 1.64 | E27: 3 | F27: 1.69 | G27: 2026-08-14 | H27: Fund's own NTA announcement | I27: 11 | J27: 0.053359 | K27: -0.029586 | N27: 1.6701 | O27: 0.011915454 | P27: Fewer than 24 months of discount history | Q27: the fund needs its own discount history in the monthly panel; until then it can be monitored but not z-scored
A28: AFI | B28: Australian Foundation Investment Company Limited | C28: AMBER | D28: 6.9099998 | E28: 3 | F28: 8.06 | G28: 2026-08-28 | H28: Fund's earlier published NTA | I28: 1 | J28: 0.013873 | K28: -0.14268 | L28: -0.073495 | M28: -1.015 | N28: 7.93 | O28: 0.016393443 | P28: NAV is estimated forward from an older figure, not published | Q28: none needed - the NAV is modelled forward from a published anchor and carries its own error band
A29: AMH | B29: AMCIL Limited | C29: AMBER | D29: 0.91000003 | E29: 3 | F29: 1.08 | G29: 2026-08-28 | H29: Fund's earlier published NTA | I29: 1 | J29: 0.009929 | K29: -0.157407 | L29: -0.117189 | M29: -1.3157 | N29: 1.08 | O29: 0 | P29: NAV is estimated forward from an older figure, not published | Q29: none needed - the NAV is modelled forward from a published anchor and carries its own error band
A30: BKI | B30: BKI Investment Company Limited | C30: AMBER | D30: 1.85 | E30: 3 | F30: 2.07 | G30: 2026-08-28 | H30: Fund's earlier published NTA | I30: 1 | J30: 0.009671 | K30: -0.10628 | L30: -0.078187 | M30: -0.6209 | N30: 2.07 | O30: 0 | P30: NAV is estimated forward from an older figure, not published | Q30: none needed - the NAV is modelled forward from a published anchor and carries its own error band
A31: DJW | B31: Djerriwarrh Investments Limited | C31: AMBER | D31: 3 | E31: 3 | F31: 3.34 | G31: 2026-08-28 | H31: Fund's earlier published NTA | I31: 1 | J31: 0.011641 | K31: -0.101796 | L31: -0.08674 | M31: -0.5542 | N31: 3.22 | O31: 0.037267081 | P31: NAV is estimated forward from an older figure, not published | Q31: none needed - the NAV is modelled forward from a published anchor and carries its own error band
A32: LSF | B32: L1 Long Short Fund Limited | C32: AMBER | D32: 4.98 | E32: 3 | F32: 4.6331 | G32: 2026-08-26 | H32: Fund's earlier published NTA | I32: 3 | J32: 0.028615 | K32: 0.074874 | L32: -0.032329 | M32: 2.4279 | N32: 4.317 | O32: 0.073222145 | P32: NAV is estimated forward from an older figure, not published | Q32: none needed - the NAV is modelled forward from a published anchor and carries its own error band
A33: MA1 | B33: MA Credit Income Trust | C33: AMBER | D33: 1.96 | E33: 3 | F33: 2.0135 | G33: 2026-08-28 | H33: Fund's earlier published NTA | I33: 1 | J33: 0.027944 | K33: -0.026571 | L33: -0.136628 | M33: 2.0311 | P33: NAV is estimated forward from an older figure, not published | Q33: none needed - the NAV is modelled forward from a published anchor and carries its own error band
A34: MIR | B34: Mirrabooka Investments Limited | C34: AMBER | D34: 2.5699999 | E34: 3 | F34: 2.74 | G34: 2026-08-28 | H34: Fund's earlier published NTA | I34: 1 | J34: 0.014244 | K34: -0.062044 | L34: -0.008795 | M34: -0.9027 | N34: 2.82 | O34: 0.028368794 | P34: NAV is estimated forward from an older figure, not published | Q34: none needed - the NAV is modelled forward from a published anchor and carries its own error band
A35: PIC | B35: Perpetual Equity Investment Company Limited | C35: AMBER | D35: 1.24 | E35: 3 | F35: 1.232 | G35: 2026-08-28 | H35: Fund's earlier published NTA | I35: 1 | J35: 0.012131 | K35: 0.006494 | L35: -0.050628 | M35: 1.6325 | N35: 1.207 | O35: 0.02071251 | P35: NAV is estimated forward from an older figure, not published | Q35: none needed - the NAV is modelled forward from a published anchor and carries its own error band
A36: PL8 | B36: Plato Income Maximiser Limited | C36: AMBER | D36: 1.4400001 | E36: 3 | F36: 1.164 | G36: 2026-08-21 | H36: Fund's earlier published NTA | I36: 6 | J36: 0.034625 | K36: 0.237113 | L36: 0.150882 | M36: 1.3539 | N36: 1.144 | O36: 0.017482517 | P36: NAV is estimated forward from an older figure, not published | Q36: none needed - the NAV is modelled forward from a published anchor and carries its own error band
A37: RF1 | B37: Regal Investment Fund | C37: AMBER | D37: 3.6199999 | E37: 3 | F37: 3.58 | G37: 2026-08-28 | H37: Fund's earlier published NTA | I37: 1 | J37: 0.018721 | K37: 0.011173 | L37: -0.066182 | M37: 1.8654 | N37: 3.67 | O37: 0.024523161 | P37: NAV is estimated forward from an older figure, not published | Q37: none needed - the NAV is modelled forward from a published anchor and carries its own error band
A38: SEC | B38: Spheria Emerging Companies Limited | C38: AMBER | D38: 2.3699999 | E38: 3 | F38: 2.311 | G38: 2026-08-27 | H38: Fund's earlier published NTA | I38: 2 | J38: 0.014402 | K38: 0.02553 | L38: -0.033714 | M38: 0.9953 | N38: 2.238 | O38: 0.032618409 | P38: NAV is estimated forward from an older figure, not published | Q38: none needed - the NAV is modelled forward from a published anchor and carries its own error band
A39: TGF | B39: Tribeca Global Natural Resources Limited | C39: AMBER | D39: 2.8499999 | E39: 3 | F39: 3.86 | G39: 2026-08-28 | H39: Fund's earlier published NTA | I39: 1 | J39: 0.023076 | K39: -0.261658 | L39: -0.231391 | M39: -0.6131 | N39: 3.486 | O39: 0.10728629 | P39: NAV is estimated forward from an older figure, not published | Q39: none needed - the NAV is modelled forward from a published anchor and carries its own error band
A40: CD1 | B40: Cd Private Equity Fund I | C40: AMBER | D40: 0.25999999 | E40: 3 | F40: 0.61 | G40: 2026-06-30 | H40: Monthly report | I40: 44 | J40: 0.195299 | K40: -0.573771 | L40: -0.353132 | M40: -3.8806 | N40: 0.59 | O40: 0.033898305 | P40: Newest NAV we hold is old | Q40: re-run the NAV harvest; the anchor is past the fresh window
A41: CDO | B41: Cadence Opportunities Fund Limited | C41: AMBER | D41: 2.29 | E41: 3 | F41: 2.194 | G41: 2026-06-30 | H41: ASX monthly report | I41: 44 | J41: 0.10621 | K41: 0.043756 | L41: -0.145223 | M41: 1.0953 | N41: 2.316 | O41: 0.052677029 | P41: Newest NAV we hold is old | Q41: re-run the NAV harvest; the anchor is past the fresh window
...

Sheet Why not green
A1: Why funds are not green
A2: Counts recalculate from the 'ASX funds' tab.
A4: Reason | B4: Funds | C4: % of all
A5: (green - nothing blocking) | B5: =COUNTIF('ASX funds'!$P$6:$P$103,"") | C5: =IFERROR(B5/$B$15,0)
A6: Discount is not far enough from its own average to beat the uncertainty in our NAV | B6: =COUNTIF('ASX funds'!$P$6:$P$103,$A6) | C6: =IFERROR(B6/$B$15,0)
A7: NAV is estimated forward from an older figure, not published | B7: =COUNTIF('ASX funds'!$P$6:$P$103,$A7) | C7: =IFERROR(B7/$B$15,0)
A8: Fewer than 24 months of discount history | B8: =COUNTIF('ASX funds'!$P$6:$P$103,$A8) | C8: =IFERROR(B8/$B$15,0)
A9: NAV jumps implausibly from this fund's own previous figure - treated as a bad reading, not a real move | B9: =COUNTIF('ASX funds'!$P$6:$P$103,$A9) | C9: =IFERROR(B9/$B$15,0)
A10: Newest NAV we hold is old | B10: =COUNTIF('ASX funds'!$P$6:$P$103,$A10) | C10: =IFERROR(B10/$B$15,0)
A11: NAV is past the age limit for alerting | B11: =COUNTIF('ASX funds'!$P$6:$P$103,$A11) | C11: =IFERROR(B11/$B$15,0)
A12: No live price - only a month-end print | B12: =COUNTIF('ASX funds'!$P$6:$P$103,$A12) | C12: =IFERROR(B12/$B$15,0)
A13: NAV is zero or negative | B13: =COUNTIF('ASX funds'!$P$6:$P$103,$A13) | C13: =IFERROR(B13/$B$15,0)
A14: No NAV from any source | B14: =COUNTIF('ASX funds'!$P$6:$P$103,$A14) | C14: =IFERROR(B14/$B$15,0)
A15: Total | B15: =SUM(B5:B14)
A17: Source: outputs/live_coverage/coverage_audit.csv, generated by the live coverage audit. A fund may have several problems; the one shown is the audit's primary blocking issue.
