Workbook

Sheet Formulas
C2: Issue | D2: Issue (from treasury) | E2: Total | F2: Rank | I2: Buybacks | J2: Rank | M2: Tender offer | N2: Capital redemption | O2: Capital distribution | P2: TotaL
B3: {=_xlfn.UNIQUE(Issuance!D4:D65536)} -> Aberdeen Equity Income Trust | C3: =SUMIFS(Issuance!$H:$H,Issuance!$D:$D,Formulas!$B3,Issuance!$C:$C,Formulas!C$2) -> 9.7169819 | D3: =SUMIFS(Issuance!$H:$H,Issuance!$D:$D,Formulas!$B3,Issuance!$C:$C,Formulas!D$2) -> 0.62175 | E3: =SUM(C3:D3) -> 10.338732 | F3: =IF(OR(B3="",B3=0,E3=0),"",IF(COUNTIFS($E$3:$E$500,">"&E3,$E$3:$E$500,"<>0")+1<=20,COUNTIFS($E$3:$E$500,">"&E3,$E$3:$E$500,"<>0")+1,"")) | H3: {=_xlfn.UNIQUE(Buybacks!D4:D64390)} -> Aberdeen Asia Focus | I3: =SUMIFS(Buybacks!H:H,Buybacks!D:D,Formulas!H3) -> -16.649146 | J3: =IF(OR(H3="",H3=0,I3=0),"",IF(COUNTIFS($I$3:$I$500,"<"&I3,$I$3:$I$500,"<>0")+1<=20,COUNTIFS($I$3:$I$500,"<"&I3,$I$3:$I$500,"<>0")+1,"")) | L3: {=_xlfn.UNIQUE('Corporate activity'!D4:D65536)} -> Aquila European Renewables | M3: =SUMIFS('Corporate activity'!$H:$H,'Corporate activity'!$D:$D,Formulas!$L3,'Corporate activity'!$C:$C,Formulas!M$2) -> 0 | N3: =SUMIFS('Corporate activity'!$H:$H,'Corporate activity'!$D:$D,Formulas!$L3,'Corporate activity'!$C:$C,Formulas!N$2) -> 0 | O3: =SUMIFS('Corporate activity'!$H:$H,'Corporate activity'!$D:$D,Formulas!$L3,'Corporate activity'!$C:$C,Formulas!O$2) -> -46.8 | P3: =SUM(M3:O3) -> -46.8 | Q3: =IF(OR(L3="",L3=0,P3=0),"",IF(COUNTIFS($P$3:$P$500,"<"&P3,$P$3:$P$500,"<>0")+1<=20,COUNTIFS($P$3:$P$500,"<"&P3,$P$3:$P$500,"<>0")+1,"")) -> 8
B4: Ashoka India Equity | C4: =SUMIFS(Issuance!$H:$H,Issuance!$D:$D,Formulas!$B4,Issuance!$C:$C,Formulas!C$2) -> 1.023525 | D4: =SUMIFS(Issuance!$H:$H,Issuance!$D:$D,Formulas!$B4,Issuance!$C:$C,Formulas!D$2) -> 0 | E4: =SUM(C4:D4) -> 1.023525 | F4: =IF(OR(B4="",B4=0,E4=0),"",IF(COUNTIFS($E$3:$E$500,">"&E4,$E$3:$E$500,"<>0")+1<=20,COUNTIFS($E$3:$E$500,">"&E4,$E$3:$E$500,"<>0")+1,"")) | H4: Aberdeen New India Investment Trust | I4: =SUMIFS(Buybacks!H:H,Buybacks!D:D,Formulas!H4) -> -13.104288 | J4: =IF(OR(H4="",H4=0,I4=0),"",IF(COUNTIFS($I$3:$I$500,"<"&I4,$I$3:$I$500,"<>0")+1<=20,COUNTIFS($I$3:$I$500,"<"&I4,$I$3:$I$500,"<>0")+1,"")) | L4: LMS Capital | M4: =SUMIFS('Corporate activity'!$H:$H,'Corporate activity'!$D:$D,Formulas!$L4,'Corporate activity'!$C:$C,Formulas!M$2) -> 0 | N4: =SUMIFS('Corporate activity'!$H:$H,'Corporate activity'!$D:$D,Formulas!$L4,'Corporate activity'!$C:$C,Formulas!N$2) -> 0 | O4: =SUMIFS('Corporate activity'!$H:$H,'Corporate activity'!$D:$D,Formulas!$L4,'Corporate activity'!$C:$C,Formulas!O$2) -> -1.614549 | P4: =SUM(M4:O4) -> -1.614549 | Q4: =IF(OR(L4="",L4=0,P4=0),"",IF(COUNTIFS($P$3:$P$500,"<"&P4,$P$3:$P$500,"<>0")+1<=20,COUNTIFS($P$3:$P$500,"<"&P4,$P$3:$P$500,"<>0")+1,""))
B5: Ashoka WhiteOak Emerging Markets | C5: =SUMIFS(Issuance!$H:$H,Issuance!$D:$D,Formulas!$B5,Issuance!$C:$C,Formulas!C$2) -> 6.1690169 | D5: =SUMIFS(Issuance!$H:$H,Issuance!$D:$D,Formulas!$B5,Issuance!$C:$C,Formulas!D$2) -> 0 | E5: =SUM(C5:D5) -> 6.1690169 | F5: =IF(OR(B5="",B5=0,E5=0),"",IF(COUNTIFS($E$3:$E$500,">"&E5,$E$3:$E$500,"<>0")+1<=20,COUNTIFS($E$3:$E$500,">"&E5,$E$3:$E$500,"<>0")+1,"")) | H5: Aberdeen UK Smaller Companies Growth | I5: =SUMIFS(Buybacks!H:H,Buybacks!D:D,Formulas!H5) -> -36.699984 | J5: =IF(OR(H5="",H5=0,I5=0),"",IF(COUNTIFS($I$3:$I$500,"<"&I5,$I$3:$I$500,"<>0")+1<=20,COUNTIFS($I$3:$I$500,"<"&I5,$I$3:$I$500,"<>0")+1,"")) | L5: Ashoka WhiteOak Emerging Markets | M5: =SUMIFS('Corporate activity'!$H:$H,'Corporate activity'!$D:$D,Formulas!$L5,'Corporate activity'!$C:$C,Formulas!M$2) -> 0 | N5: =SUMIFS('Corporate activity'!$H:$H,'Corporate activity'!$D:$D,Formulas!$L5,'Corporate activity'!$C:$C,Formulas!N$2) -> -0.137202 | O5: =SUMIFS('Corporate activity'!$H:$H,'Corporate activity'!$D:$D,Formulas!$L5,'Corporate activity'!$C:$C,Formulas!O$2) -> 0 | P5: =SUM(M5:O5) -> -0.137202 | Q5: =IF(OR(L5="",L5=0,P5=0),"",IF(COUNTIFS($P$3:$P$500,"<"&P5,$P$3:$P$500,"<>0")+1<=20,COUNTIFS($P$3:$P$500,"<"&P5,$P$3:$P$500,"<>0")+1,""))
B6: City of London Investment Trust | C6: =SUMIFS(Issuance!$H:$H,Issuance!$D:$D,Formulas!$B6,Issuance!$C:$C,Formulas!C$2) -> 63.3275 | D6: =SUMIFS(Issuance!$H:$H,Issuance!$D:$D,Formulas!$B6,Issuance!$C:$C,Formulas!D$2) -> 0 | E6: =SUM(C6:D6) -> 63.3275 | F6: =IF(OR(B6="",B6=0,E6=0),"",IF(COUNTIFS($E$3:$E$500,">"&E6,$E$3:$E$500,"<>0")+1<=20,COUNTIFS($E$3:$E$500,">"&E6,$E$3:$E$500,"<>0")+1,"")) -> 5 | H6: Aberforth Smaller Companies | I6: =SUMIFS(Buybacks!H:H,Buybacks!D:D,Formulas!H6) -> -43.30337 | J6: =IF(OR(H6="",H6=0,I6=0),"",IF(COUNTIFS($I$3:$I$500,"<"&I6,$I$3:$I$500,"<>0")+1<=20,COUNTIFS($I$3:$I$500,"<"&I6,$I$3:$I$500,"<>0")+1,"")) | L6: JPEL Private Equity | M6: =SUMIFS('Corporate activity'!$H:$H,'Corporate activity'!$D:$D,Formulas!$L6,'Corporate activity'!$C:$C,Formulas!M$2) -> 0 | N6: =SUMIFS('Corporate activity'!$H:$H,'Corporate activity'!$D:$D,Formulas!$L6,'Corporate activity'!$C:$C,Formulas!N$2) -> -4.461816 | O6: =SUMIFS('Corporate activity'!$H:$H,'Corporate activity'!$D:$D,Formulas!$L6,'Corporate activity'!$C:$C,Formulas!O$2) -> 0 | P6: =SUM(M6:O6) -> -4.461816 | Q6: =IF(OR(L6="",L6=0,P6=0),"",IF(COUNTIFS($P$3:$P$500,"<"&P6,$P$3:$P$500,"<>0")+1<=20,COUNTIFS($P$3:$P$500,"<"&P6,$P$3:$P$500,"<>0")+1,""))
B7: CQS New City High Yield Fund | C7: =SUMIFS(Issuance!$H:$H,Issuance!$D:$D,Formulas!$B7,Issuance!$C:$C,Formulas!C$2) -> 17.700425 | D7: =SUMIFS(Issuance!$H:$H,Issuance!$D:$D,Formulas!$B7,Issuance!$C:$C,Formulas!D$2) -> 0 | E7: =SUM(C7:D7) -> 17.700425 | F7: =IF(OR(B7="",B7=0,E7=0),"",IF(COUNTIFS($E$3:$E$500,">"&E7,$E$3:$E$500,"<>0")+1<=20,COUNTIFS($E$3:$E$500,">"&E7,$E$3:$E$500,"<>0")+1,"")) -> 16 | H7: Alliance Witan | I7: =SUMIFS(Buybacks!H:H,Buybacks!D:D,Formulas!H7) -> -141.56233 | J7: =IF(OR(H7="",H7=0,I7=0),"",IF(COUNTIFS($I$3:$I$500,"<"&I7,$I$3:$I$500,"<>0")+1<=20,COUNTIFS($I$3:$I$500,"<"&I7,$I$3:$I$500,"<>0")+1,"")) -> 7 | L7: Doric Nimrod Air Three | M7: =SUMIFS('Corporate activity'!$H:$H,'Corporate activity'!$D:$D,Formulas!$L7,'Corporate activity'!$C:$C,Formulas!M$2) -> 0 | N7: =SUMIFS('Corporate activity'!$H:$H,'Corporate activity'!$D:$D,Formulas!$L7,'Corporate activity'!$C:$C,Formulas!N$2) -> 0 | O7: =SUMIFS('Corporate activity'!$H:$H,'Corporate activity'!$D:$D,Formulas!$L7,'Corporate activity'!$C:$C,Formulas!O$2) -> 0 | P7: =SUM(M7:O7) -> 0 | Q7: =IF(OR(L7="",L7=0,P7=0),"",IF(COUNTIFS($P$3:$P$500,"<"&P7,$P$3:$P$500,"<>0")+1<=20,COUNTIFS($P$3:$P$500,"<"&P7,$P$3:$P$500,"<>0")+1,""))
B8: CT Global Managed Portfolio Growth | C8: =SUMIFS(Issuance!$H:$H,Issuance!$D:$D,Formulas!$B8,Issuance!$C:$C,Formulas!C$2) -> 0.549625 | D8: =SUMIFS(Issuance!$H:$H,Issuance!$D:$D,Formulas!$B8,Issuance!$C:$C,Formulas!D$2) -> 0.6055 | E8: =SUM(C8:D8) -> 1.155125 | F8: =IF(OR(B8="",B8=0,E8=0),"",IF(COUNTIFS($E$3:$E$500,">"&E8,$E$3:$E$500,"<>0")+1<=20,COUNTIFS($E$3:$E$500,">"&E8,$E$3:$E$500,"<>0")+1,"")) | H8: Allianz Technology Trust | I8: =SUMIFS(Buybacks!H:H,Buybacks!D:D,Formulas!H8) -> -160.62452 | J8: =IF(OR(H8="",H8=0,I8=0),"",IF(COUNTIFS($I$3:$I$500,"<"&I8,$I$3:$I$500,"<>0")+1<=20,COUNTIFS($I$3:$I$500,"<"&I8,$I$3:$I$500,"<>0")+1,"")) -> 3 | L8: PRS REIT | M8: =SUMIFS('Corporate activity'!$H:$H,'Corporate activity'!$D:$D,Formulas!$L8,'Corporate activity'!$C:$C,Formulas!M$2) -> 0 | N8: =SUMIFS('Corporate activity'!$H:$H,'Corporate activity'!$D:$D,Formulas!$L8,'Corporate activity'!$C:$C,Formulas!N$2) -> 0 | O8: =SUMIFS('Corporate activity'!$H:$H,'Corporate activity'!$D:$D,Formulas!$L8,'Corporate activity'!$C:$C,Formulas!O$2) -> 0 | P8: =SUM(M8:O8) -> 0 | Q8: =IF(OR(L8="",L8=0,P8=0),"",IF(COUNTIFS($P$3:$P$500,"<"&P8,$P$3:$P$500,"<>0")+1<=20,COUNTIFS($P$3:$P$500,"<"&P8,$P$3:$P$500,"<>0")+1,""))
B9: CT Global Managed Portfolio Income | C9: =SUMIFS(Issuance!$H:$H,Issuance!$D:$D,Formulas!$B9,Issuance!$C:$C,Formulas!C$2) -> 3.7655205 | D9: =SUMIFS(Issuance!$H:$H,Issuance!$D:$D,Formulas!$B9,Issuance!$C:$C,Formulas!D$2) -> 0 | E9: =SUM(C9:D9) -> 3.7655205 | F9: =IF(OR(B9="",B9=0,E9=0),"",IF(COUNTIFS($E$3:$E$500,">"&E9,$E$3:$E$500,"<>0")+1<=20,COUNTIFS($E$3:$E$500,">"&E9,$E$3:$E$500,"<>0")+1,"")) | H9: Artemis UK Future Leaders | I9: =SUMIFS(Buybacks!H:H,Buybacks!D:D,Formulas!H9) -> -2.6335214 | J9: =IF(OR(H9="",H9=0,I9=0),"",IF(COUNTIFS($I$3:$I$500,"<"&I9,$I$3:$I$500,"<>0")+1<=20,COUNTIFS($I$3:$I$500,"<"&I9,$I$3:$I$500,"<>0")+1,"")) | L9: Aberdeen Equity Income Trust | M9: =SUMIFS('Corporate activity'!$H:$H,'Corporate activity'!$D:$D,Formulas!$L9,'Corporate activity'!$C:$C,Formulas!M$2) -> 0 | N9: =SUMIFS('Corporate activity'!$H:$H,'Corporate activity'!$D:$D,Formulas!$L9,'Corporate activity'!$C:$C,Formulas!N$2) -> 0 | O9: =SUMIFS('Corporate activity'!$H:$H,'Corporate activity'!$D:$D,Formulas!$L9,'Corporate activity'!$C:$C,Formulas!O$2) -> 0 | P9: =SUM(M9:O9) -> 0 | Q9: =IF(OR(L9="",L9=0,P9=0),"",IF(COUNTIFS($P$3:$P$500,"<"&P9,$P$3:$P$500,"<>0")+1<=20,COUNTIFS($P$3:$P$500,"<"&P9,$P$3:$P$500,"<>0")+1,""))
B10: EJF Investments | C10: =SUMIFS(Issuance!$H:$H,Issuance!$D:$D,Formulas!$B10,Issuance!$C:$C,Formulas!C$2) -> 8.6486295 | D10: =SUMIFS(Issuance!$H:$H,Issuance!$D:$D,Formulas!$B10,Issuance!$C:$C,Formulas!D$2) -> 0 | E10: =SUM(C10:D10) -> 8.6486295 | F10: =IF(OR(B10="",B10=0,E10=0),"",IF(COUNTIFS($E$3:$E$500,">"&E10,$E$3:$E$500,"<>0")+1<=20,COUNTIFS($E$3:$E$500,">"&E10,$E$3:$E$500,"<>0")+1,"")) | H10: AVI Global Trust | I10: =SUMIFS(Buybacks!H:H,Buybacks!D:D,Formulas!H10) -> -40.507971 | J10: =IF(OR(H10="",H10=0,I10=0),"",IF(COUNTIFS($I$3:$I$500,"<"&I10,$I$3:$I$500,"<>0")+1<=20,COUNTIFS($I$3:$I$500,"<"&I10,$I$3:$I$500,"<>0")+1,"")) | L10: Athelney Trust | M10: =SUMIFS('Corporate activity'!$H:$H,'Corporate activity'!$D:$D,Formulas!$L10,'Corporate activity'!$C:$C,Formulas!M$2) -> 0 | N10: =SUMIFS('Corporate activity'!$H:$H,'Corporate activity'!$D:$D,Formulas!$L10,'Corporate activity'!$C:$C,Formulas!N$2) -> 0 | O10: =SUMIFS('Corporate activity'!$H:$H,'Corporate activity'!$D:$D,Formulas!$L10,'Corporate activity'!$C:$C,Formulas!O$2) -> 0 | P10: =SUM(M10:O10) -> 0 | Q10: =IF(OR(L10="",L10=0,P10=0),"",IF(COUNTIFS($P$3:$P$500,"<"&P10,$P$3:$P$500,"<>0")+1<=20,COUNTIFS($P$3:$P$500,"<"&P10,$P$3:$P$500,"<>0")+1,""))
B11: Henderson Far East Income | C11: =SUMIFS(Issuance!$H:$H,Issuance!$D:$D,Formulas!$B11,Issuance!$C:$C,Formulas!C$2) -> 90.027288 | D11: =SUMIFS(Issuance!$H:$H,Issuance!$D:$D,Formulas!$B11,Issuance!$C:$C,Formulas!D$2) -> 0 | E11: =SUM(C11:D11) -> 90.027288 | F11: =IF(OR(B11="",B11=0,E11=0),"",IF(COUNTIFS($E$3:$E$500,">"&E11,$E$3:$E$500,"<>0")+1<=20,COUNTIFS($E$3:$E$500,">"&E11,$E$3:$E$500,"<>0")+1,"")) -> 4 | H11: Baillie Gifford China Growth | I11: =SUMIFS(Buybacks!H:H,Buybacks!D:D,Formulas!H11) -> -9.4854534 | J11: =IF(OR(H11="",H11=0,I11=0),"",IF(COUNTIFS($I$3:$I$500,"<"&I11,$I$3:$I$500,"<>0")+1<=20,COUNTIFS($I$3:$I$500,"<"&I11,$I$3:$I$500,"<>0")+1,"")) | L11: Develop North | M11: =SUMIFS('Corporate activity'!$H:$H,'Corporate activity'!$D:$D,Formulas!$L11,'Corporate activity'!$C:$C,Formulas!M$2) -> 0 | N11: =SUMIFS('Corporate activity'!$H:$H,'Corporate activity'!$D:$D,Formulas!$L11,'Corporate activity'!$C:$C,Formulas!N$2) -> 0 | O11: =SUMIFS('Corporate activity'!$H:$H,'Corporate activity'!$D:$D,Formulas!$L11,'Corporate activity'!$C:$C,Formulas!O$2) -> 0 | P11: =SUM(M11:O11) -> 0 | Q11: =IF(OR(L11="",L11=0,P11=0),"",IF(COUNTIFS($P$3:$P$500,"<"&P11,$P$3:$P$500,"<>0")+1<=20,COUNTIFS($P$3:$P$500,"<"&P11,$P$3:$P$500,"<>0")+1,""))
B12: Invesco Bond Income Plus | C12: =SUMIFS(Issuance!$H:$H,Issuance!$D:$D,Formulas!$B12,Issuance!$C:$C,Formulas!C$2) -> 98.909156 | D12: =SUMIFS(Issuance!$H:$H,Issuance!$D:$D,Formulas!$B12,Issuance!$C:$C,Formulas!D$2) -> 0 | E12: =SUM(C12:D12) -> 98.909156 | F12: =IF(OR(B12="",B12=0,E12=0),"",IF(COUNTIFS($E$3:$E$500,">"&E12,$E$3:$E$500,"<>0")+1<=20,COUNTIFS($E$3:$E$500,">"&E12,$E$3:$E$500,"<>0")+1,"")) -> 3 | H12: Baillie Gifford European Growth | I12: =SUMIFS(Buybacks!H:H,Buybacks!D:D,Formulas!H12) -> -17.920472 | J12: =IF(OR(H12="",H12=0,I12=0),"",IF(COUNTIFS($I$3:$I$500,"<"&I12,$I$3:$I$500,"<>0")+1<=20,COUNTIFS($I$3:$I$500,"<"&I12,$I$3:$I$500,"<>0")+1,"")) | L12: Global Opportunities | M12: =SUMIFS('Corporate activity'!$H:$H,'Corporate activity'!$D:$D,Formulas!$L12,'Corporate activity'!$C:$C,Formulas!M$2) -> 0 | N12: =SUMIFS('Corporate activity'!$H:$H,'Corporate activity'!$D:$D,Formulas!$L12,'Corporate activity'!$C:$C,Formulas!N$2) -> 0 | O12: =SUMIFS('Corporate activity'!$H:$H,'Corporate activity'!$D:$D,Formulas!$L12,'Corporate activity'!$C:$C,Formulas!O$2) -> 0 | P12: =SUM(M12:O12) -> 0 | Q12: =IF(OR(L12="",L12=0,P12=0),"",IF(COUNTIFS($P$3:$P$500,"<"&P12,$P$3:$P$500,"<>0")+1<=20,COUNTIFS($P$3:$P$500,"<"&P12,$P$3:$P$500,"<>0")+1,""))
B13: M&G Credit Income | C13: =SUMIFS(Issuance!$H:$H,Issuance!$D:$D,Formulas!$B13,Issuance!$C:$C,Formulas!C$2) -> 6.9309 | D13: =SUMIFS(Issuance!$H:$H,Issuance!$D:$D,Formulas!$B13,Issuance!$C:$C,Formulas!D$2) -> 0.0932 | E13: =SUM(C13:D13) -> 7.0241 | F13: =IF(OR(B13="",B13=0,E13=0),"",IF(COUNTIFS($E$3:$E$500,">"&E13,$E$3:$E$500,"<>0")+1<=20,COUNTIFS($E$3:$E$500,">"&E13,$E$3:$E$500,"<>0")+1,"")) | H13: Baillie Gifford Japan Trust | I13: =SUMIFS(Buybacks!H:H,Buybacks!D:D,Formulas!H13) -> -97.394717 | J13: =IF(OR(H13="",H13=0,I13=0),"",IF(COUNTIFS($I$3:$I$500,"<"&I13,$I$3:$I$500,"<>0")+1<=20,COUNTIFS($I$3:$I$500,"<"&I13,$I$3:$I$500,"<>0")+1,"")) -> 11 | L13: Volta Finance | M13: =SUMIFS('Corporate activity'!$H:$H,'Corporate activity'!$D:$D,Formulas!$L13,'Corporate activity'!$C:$C,Formulas!M$2) -> 0 | N13: =SUMIFS('Corporate activity'!$H:$H,'Corporate activity'!$D:$D,Formulas!$L13,'Corporate activity'!$C:$C,Formulas!N$2) -> 0 | O13: =SUMIFS('Corporate activity'!$H:$H,'Corporate activity'!$D:$D,Formulas!$L13,'Corporate activity'!$C:$C,Formulas!O$2) -> 0 | P13: =SUM(M13:O13) -> 0 | Q13: =IF(OR(L13="",L13=0,P13=0),"",IF(COUNTIFS($P$3:$P$500,"<"&P13,$P$3:$P$500,"<>0")+1<=20,COUNTIFS($P$3:$P$500,"<"&P13,$P$3:$P$500,"<>0")+1,""))
B14: Odyssean Investment Trust | C14: =SUMIFS(Issuance!$H:$H,Issuance!$D:$D,Formulas!$B14,Issuance!$C:$C,Formulas!C$2) -> 12.324713 | D14: =SUMIFS(Issuance!$H:$H,Issuance!$D:$D,Formulas!$B14,Issuance!$C:$C,Formulas!D$2) -> 0 | E14: =SUM(C14:D14) -> 12.324713 | F14: =IF(OR(B14="",B14=0,E14=0),"",IF(COUNTIFS($E$3:$E$500,">"&E14,$E$3:$E$500,"<>0")+1<=20,COUNTIFS($E$3:$E$500,">"&E14,$E$3:$E$500,"<>0")+1,"")) -> 18 | H14: Baillie Gifford Shin Nippon | I14: =SUMIFS(Buybacks!H:H,Buybacks!D:D,Formulas!H14) -> -20.471347 | J14: =IF(OR(H14="",H14=0,I14=0),"",IF(COUNTIFS($I$3:$I$500,"<"&I14,$I$3:$I$500,"<>0")+1<=20,COUNTIFS($I$3:$I$500,"<"&I14,$I$3:$I$500,"<>0")+1,"")) | L14: N/A | M14: =SUMIFS('Corporate activity'!$H:$H,'Corporate activity'!$D:$D,Formulas!$L14,'Corporate activity'!$C:$C,Formulas!M$2) -> 0 | N14: =SUMIFS('Corporate activity'!$H:$H,'Corporate activity'!$D:$D,Formulas!$L14,'Corporate activity'!$C:$C,Formulas!N$2) -> 0 | O14: =SUMIFS('Corporate activity'!$H:$H,'Corporate activity'!$D:$D,Formulas!$L14,'Corporate activity'!$C:$C,Formulas!O$2) -> 0 | P14: =SUM(M14:O14) -> 0 | Q14: =IF(OR(L14="",L14=0,P14=0),"",IF(COUNTIFS($P$3:$P$500,"<"&P14,$P$3:$P$500,"<>0")+1<=20,COUNTIFS($P$3:$P$500,"<"&P14,$P$3:$P$500,"<>0")+1,""))
B15: Onward Opportunities | C15: =SUMIFS(Issuance!$H:$H,Issuance!$D:$D,Formulas!$B15,Issuance!$C:$C,Formulas!C$2) -> 6.0800468 | D15: =SUMIFS(Issuance!$H:$H,Issuance!$D:$D,Formulas!$B15,Issuance!$C:$C,Formulas!D$2) -> 0 | E15: =SUM(C15:D15) -> 6.0800468 | F15: =IF(OR(B15="",B15=0,E15=0),"",IF(COUNTIFS($E$3:$E$500,">"&E15,$E$3:$E$500,"<>0")+1<=20,COUNTIFS($E$3:$E$500,">"&E15,$E$3:$E$500,"<>0")+1,"")) | H15: Baillie Gifford UK Growth | I15: =SUMIFS(Buybacks!H:H,Buybacks!D:D,Formulas!H15) -> -18.535714 | J15: =IF(OR(H15="",H15=0,I15=0),"",IF(COUNTIFS($I$3:$I$500,"<"&I15,$I$3:$I$500,"<>0")+1<=20,COUNTIFS($I$3:$I$500,"<"&I15,$I$3:$I$500,"<>0")+1,"")) | L15: JPMorgan Global Emerging Markets Income | M15: =SUMIFS('Corporate activity'!$H:$H,'Corporate activity'!$D:$D,Formulas!$L15,'Corporate activity'!$C:$C,Formulas!M$2) -> 0 | N15: =SUMIFS('Corporate activity'!$H:$H,'Corporate activity'!$D:$D,Formulas!$L15,'Corporate activity'!$C:$C,Formulas!N$2) -> 0 | O15: =SUMIFS('Corporate activity'!$H:$H,'Corporate activity'!$D:$D,Formulas!$L15,'Corporate activity'!$C:$C,Formulas!O$2) -> 0 | P15: =SUM(M15:O15) -> 0 | Q15: =IF(OR(L15="",L15=0,P15=0),"",IF(COUNTIFS($P$3:$P$500,"<"&P15,$P$3:$P$500,"<>0")+1<=20,COUNTIFS($P$3:$P$500,"<"&P15,$P$3:$P$500,"<>0")+1,""))
... B49: BlackRock World Mining | C49: =SUMIFS(Issuance!$H:$H,Issuance!$D:$D,Formulas!$B49,Issuance!$C:$C,Formulas!C$2) -> 0 | D49: =SUMIFS(Issuance!$H:$H,Issuance!$D:$D,Formulas!$B49,Issuance!$C:$C,Formulas!D$2) -> 4.65128 | E49: =SUM(C49:D49) -> 4.65128 | F49: =IF(OR(B49="",B49=0,E49=0),"",IF(COUNTIFS($E$3:$E$500,">"&E49,$E$3:$E$500,"<>0")+1<=20,COUNTIFS($E$3:$E$500,">"&E49,$E$3:$E$500,"<>0")+1,"")) | H49: International Public Partnerships | I49: =SUMIFS(Buybacks!H:H,Buybacks!D:D,Formulas!H49) -> -28.869252 | J49: =IF(OR(H49="",H49=0,I49=0),"",IF(COUNTIFS($I$3:$I$500,"<"&I49,$I$3:$I$500,"<>0")+1<=20,COUNTIFS($I$3:$I$500,"<"&I49,$I$3:$I$500,"<>0")+1,"")) | L49: Schroder Japan Trust | M49: =SUMIFS('Corporate activity'!$H:$H,'Corporate activity'!$D:$D,Formulas!$L49,'Corporate activity'!$C:$C,Formulas!M$2) -> 0 | N49: =SUMIFS('Corporate activity'!$H:$H,'Corporate activity'!$D:$D,Formulas!$L49,'Corporate activity'!$C:$C,Formulas!N$2) -> 0 | O49: =SUMIFS('Corporate activity'!$H:$H,'Corporate activity'!$D:$D,Formulas!$L49,'Corporate activity'!$C:$C,Formulas!O$2) -> 0 | P49: =SUM(M49:O49) -> 0 | Q49: =IF(OR(L49="",L49=0,P49=0),"",IF(COUNTIFS($P$3:$P$500,"<"&P49,$P$3:$P$500,"<>0")+1<=20,COUNTIFS($P$3:$P$500,"<"&P49,$P$3:$P$500,"<>0")+1,""))
B50: 0 | C50: =SUMIFS(Issuance!$H:$H,Issuance!$D:$D,Formulas!$B50,Issuance!$C:$C,Formulas!C$2) -> 0 | D50: =SUMIFS(Issuance!$H:$H,Issuance!$D:$D,Formulas!$B50,Issuance!$C:$C,Formulas!D$2) -> 0 | E50: =SUM(C50:D50) -> 0 | F50: =IF(OR(B50="",B50=0,E50=0),"",IF(COUNTIFS($E$3:$E$500,">"&E50,$E$3:$E$500,"<>0")+1<=20,COUNTIFS($E$3:$E$500,">"&E50,$E$3:$E$500,"<>0")+1,"")) | H50: Invesco Asia Dragon Trust | I50: =SUMIFS(Buybacks!H:H,Buybacks!D:D,Formulas!H50) -> -22.123445 | J50: =IF(OR(H50="",H50=0,I50=0),"",IF(COUNTIFS($I$3:$I$500,"<"&I50,$I$3:$I$500,"<>0")+1<=20,COUNTIFS($I$3:$I$500,"<"&I50,$I$3:$I$500,"<>0")+1,"")) | L50: Cordiant Digital Infrastructure | M50: =SUMIFS('Corporate activity'!$H:$H,'Corporate activity'!$D:$D,Formulas!$L50,'Corporate activity'!$C:$C,Formulas!M$2) -> 0 | N50: =SUMIFS('Corporate activity'!$H:$H,'Corporate activity'!$D:$D,Formulas!$L50,'Corporate activity'!$C:$C,Formulas!N$2) -> 0 | O50: =SUMIFS('Corporate activity'!$H:$H,'Corporate activity'!$D:$D,Formulas!$L50,'Corporate activity'!$C:$C,Formulas!O$2) -> 0 | P50: =SUM(M50:O50) -> 0 | Q50: =IF(OR(L50="",L50=0,P50=0),"",IF(COUNTIFS($P$3:$P$500,"<"&P50,$P$3:$P$500,"<>0")+1<=20,COUNTIFS($P$3:$P$500,"<"&P50,$P$3:$P$500,"<>0")+1,""))
C51: =SUMIFS(Issuance!$H:$H,Issuance!$D:$D,Formulas!$B51,Issuance!$C:$C,Formulas!C$2) -> 0 | D51: =SUMIFS(Issuance!$H:$H,Issuance!$D:$D,Formulas!$B51,Issuance!$C:$C,Formulas!D$2) -> 0 | E51: =SUM(C51:D51) -> 0 | F51: =IF(OR(B51="",B51=0,E51=0),"",IF(COUNTIFS($E$3:$E$500,">"&E51,$E$3:$E$500,"<>0")+1<=20,COUNTIFS($E$3:$E$500,">"&E51,$E$3:$E$500,"<>0")+1,"")) | H51: JPEL Private Equity | I51: =SUMIFS(Buybacks!H:H,Buybacks!D:D,Formulas!H51) -> -4.4652025 | J51: =IF(OR(H51="",H51=0,I51=0),"",IF(COUNTIFS($I$3:$I$500,"<"&I51,$I$3:$I$500,"<>0")+1<=20,COUNTIFS($I$3:$I$500,"<"&I51,$I$3:$I$500,"<>0")+1,"")) | L51: Onward Opportunities | M51: =SUMIFS('Corporate activity'!$H:$H,'Corporate activity'!$D:$D,Formulas!$L51,'Corporate activity'!$C:$C,Formulas!M$2) -> 0 | N51: =SUMIFS('Corporate activity'!$H:$H,'Corporate activity'!$D:$D,Formulas!$L51,'Corporate activity'!$C:$C,Formulas!N$2) -> 0 | O51: =SUMIFS('Corporate activity'!$H:$H,'Corporate activity'!$D:$D,Formulas!$L51,'Corporate activity'!$C:$C,Formulas!O$2) -> 0 | P51: =SUM(M51:O51) -> 0 | Q51: =IF(OR(L51="",L51=0,P51=0),"",IF(COUNTIFS($P$3:$P$500,"<"&P51,$P$3:$P$500,"<>0")+1<=20,COUNTIFS($P$3:$P$500,"<"&P51,$P$3:$P$500,"<>0")+1,""))
C52: =SUMIFS(Issuance!$H:$H,Issuance!$D:$D,Formulas!$B52,Issuance!$C:$C,Formulas!C$2) -> 0 | D52: =SUMIFS(Issuance!$H:$H,Issuance!$D:$D,Formulas!$B52,Issuance!$C:$C,Formulas!D$2) -> 0 | E52: =SUM(C52:D52) -> 0 | F52: =IF(OR(B52="",B52=0,E52=0),"",IF(COUNTIFS($E$3:$E$500,">"&E52,$E$3:$E$500,"<>0")+1<=20,COUNTIFS($E$3:$E$500,">"&E52,$E$3:$E$500,"<>0")+1,"")) | H52: JPMorgan American | I52: =SUMIFS(Buybacks!H:H,Buybacks!D:D,Formulas!H52) -> -50.287901 | J52: =IF(OR(H52="",H52=0,I52=0),"",IF(COUNTIFS($I$3:$I$500,"<"&I52,$I$3:$I$500,"<>0")+1<=20,COUNTIFS($I$3:$I$500,"<"&I52,$I$3:$I$500,"<>0")+1,"")) | L52: Aquila Energy Efficiency | M52: =SUMIFS('Corporate activity'!$H:$H,'Corporate activity'!$D:$D,Formulas!$L52,'Corporate activity'!$C:$C,Formulas!M$2) -> 0 | N52: =SUMIFS('Corporate activity'!$H:$H,'Corporate activity'!$D:$D,Formulas!$L52,'Corporate activity'!$C:$C,Formulas!N$2) -> 0 | O52: =SUMIFS('Corporate activity'!$H:$H,'Corporate activity'!$D:$D,Formulas!$L52,'Corporate activity'!$C:$C,Formulas!O$2) -> 0 | P52: =SUM(M52:O52) -> 0 | Q52: =IF(OR(L52="",L52=0,P52=0),"",IF(COUNTIFS($P$3:$P$500,"<"&P52,$P$3:$P$500,"<>0")+1<=20,COUNTIFS($P$3:$P$500,"<"&P52,$P$3:$P$500,"<>0")+1,""))
C53: =SUMIFS(Issuance!$H:$H,Issuance!$D:$D,Formulas!$B53,Issuance!$C:$C,Formulas!C$2) -> 0 | D53: =SUMIFS(Issuance!$H:$H,Issuance!$D:$D,Formulas!$B53,Issuance!$C:$C,Formulas!D$2) -> 0 | E53: =SUM(C53:D53) -> 0 | F53: =IF(OR(B53="",B53=0,E53=0),"",IF(COUNTIFS($E$3:$E$500,">"&E53,$E$3:$E$500,"<>0")+1<=20,COUNTIFS($E$3:$E$500,">"&E53,$E$3:$E$500,"<>0")+1,"")) | H53: JPMorgan Emerging Markets Growth & Income | I53: =SUMIFS(Buybacks!H:H,Buybacks!D:D,Formulas!H53) -> -46.271991 | J53: =IF(OR(H53="",H53=0,I53=0),"",IF(COUNTIFS($I$3:$I$500,"<"&I53,$I$3:$I$500,"<>0")+1<=20,COUNTIFS($I$3:$I$500,"<"&I53,$I$3:$I$500,"<>0")+1,"")) | L53: Crystal Amber Fund | M53: =SUMIFS('Corporate activity'!$H:$H,'Corporate activity'!$D:$D,Formulas!$L53,'Corporate activity'!$C:$C,Formulas!M$2) -> 0 | N53: =SUMIFS('Corporate activity'!$H:$H,'Corporate activity'!$D:$D,Formulas!$L53,'Corporate activity'!$C:$C,Formulas!N$2) -> 0 | O53: =SUMIFS('Corporate activity'!$H:$H,'Corporate activity'!$D:$D,Formulas!$L53,'Corporate activity'!$C:$C,Formulas!O$2) -> 0 | P53: =SUM(M53:O53) -> 0 | Q53: =IF(OR(L53="",L53=0,P53=0),"",IF(COUNTIFS($P$3:$P$500,"<"&P53,$P$3:$P$500,"<>0")+1<=20,COUNTIFS($P$3:$P$500,"<"&P53,$P$3:$P$500,"<>0")+1,""))
C54: =SUMIFS(Issuance!$H:$H,Issuance!$D:$D,Formulas!$B54,Issuance!$C:$C,Formulas!C$2) -> 0 | D54: =SUMIFS(Issuance!$H:$H,Issuance!$D:$D,Formulas!$B54,Issuance!$C:$C,Formulas!D$2) -> 0 | E54: =SUM(C54:D54) -> 0 | F54: =IF(OR(B54="",B54=0,E54=0),"",IF(COUNTIFS($E$3:$E$500,">"&E54,$E$3:$E$500,"<>0")+1<=20,COUNTIFS($E$3:$E$500,">"&E54,$E$3:$E$500,"<>0")+1,"")) | H54: JPMorgan Global Growth & Income | I54: =SUMIFS(Buybacks!H:H,Buybacks!D:D,Formulas!H54) -> -88.062386 | J54: =IF(OR(H54="",H54=0,I54=0),"",IF(COUNTIFS($I$3:$I$500,"<"&I54,$I$3:$I$500,"<>0")+1<=20,COUNTIFS($I$3:$I$500,"<"&I54,$I$3:$I$500,"<>0")+1,"")) -> 14 | L54: BlackRock Smaller Companies | M54: =SUMIFS('Corporate activity'!$H:$H,'Corporate activity'!$D:$D,Formulas!$L54,'Corporate activity'!$C:$C,Formulas!M$2) -> -162.91717 | N54: =SUMIFS('Corporate activity'!$H:$H,'Corporate activity'!$D:$D,Formulas!$L54,'Corporate activity'!$C:$C,Formulas!N$2) -> 0 | O54: =SUMIFS('Corporate activity'!$H:$H,'Corporate activity'!$D:$D,Formulas!$L54,'Corporate activity'!$C:$C,Formulas!O$2) -> 0 | P54: =SUM(M54:O54) -> -162.91717 | Q54: =IF(OR(L54="",L54=0,P54=0),"",IF(COUNTIFS($P$3:$P$500,"<"&P54,$P$3:$P$500,"<>0")+1<=20,COUNTIFS($P$3:$P$500,"<"&P54,$P$3:$P$500,"<>0")+1,"")) -> 5
C55: =SUMIFS(Issuance!$H:$H,Issuance!$D:$D,Formulas!$B55,Issuance!$C:$C,Formulas!C$2) -> 0 | D55: =SUMIFS(Issuance!$H:$H,Issuance!$D:$D,Formulas!$B55,Issuance!$C:$C,Formulas!D$2) -> 0 | E55: =SUM(C55:D55) -> 0 | F55: =IF(OR(B55="",B55=0,E55=0),"",IF(COUNTIFS($E$3:$E$500,">"&E55,$E$3:$E$500,"<>0")+1<=20,COUNTIFS($E$3:$E$500,">"&E55,$E$3:$E$500,"<>0")+1,"")) | H55: JPMorgan India Growth & Income | I55: =SUMIFS(Buybacks!H:H,Buybacks!D:D,Formulas!H55) -> -11.4882 | J55: =IF(OR(H55="",H55=0,I55=0),"",IF(COUNTIFS($I$3:$I$500,"<"&I55,$I$3:$I$500,"<>0")+1<=20,COUNTIFS($I$3:$I$500,"<"&I55,$I$3:$I$500,"<>0")+1,"")) | L55: Scottish Mortgage | M55: =SUMIFS('Corporate activity'!$H:$H,'Corporate activity'!$D:$D,Formulas!$L55,'Corporate activity'!$C:$C,Formulas!M$2) -> 0 | N55: =SUMIFS('Corporate activity'!$H:$H,'Corporate activity'!$D:$D,Formulas!$L55,'Corporate activity'!$C:$C,Formulas!N$2) -> 0 | O55: =SUMIFS('Corporate activity'!$H:$H,'Corporate activity'!$D:$D,Formulas!$L55,'Corporate activity'!$C:$C,Formulas!O$2) -> 0 | P55: =SUM(M55:O55) -> 0 | Q55: =IF(OR(L55="",L55=0,P55=0),"",IF(COUNTIFS($P$3:$P$500,"<"&P55,$P$3:$P$500,"<>0")+1<=20,COUNTIFS($P$3:$P$500,"<"&P55,$P$3:$P$500,"<>0")+1,""))
C56: =SUMIFS(Issuance!$H:$H,Issuance!$D:$D,Formulas!$B56,Issuance!$C:$C,Formulas!C$2) -> 0 | D56: =SUMIFS(Issuance!$H:$H,Issuance!$D:$D,Formulas!$B56,Issuance!$C:$C,Formulas!D$2) -> 0 | E56: =SUM(C56:D56) -> 0 | F56: =IF(OR(B56="",B56=0,E56=0),"",IF(COUNTIFS($E$3:$E$500,">"&E56,$E$3:$E$500,"<>0")+1<=20,COUNTIFS($E$3:$E$500,">"&E56,$E$3:$E$500,"<>0")+1,"")) | H56: JPMorgan Japanese | I56: =SUMIFS(Buybacks!H:H,Buybacks!D:D,Formulas!H56) -> -61.268784 | J56: =IF(OR(H56="",H56=0,I56=0),"",IF(COUNTIFS($I$3:$I$500,"<"&I56,$I$3:$I$500,"<>0")+1<=20,COUNTIFS($I$3:$I$500,"<"&I56,$I$3:$I$500,"<>0")+1,"")) | L56: Hydrogen Capital Growth | M56: =SUMIFS('Corporate activity'!$H:$H,'Corporate activity'!$D:$D,Formulas!$L56,'Corporate activity'!$C:$C,Formulas!M$2) -> 0 | N56: =SUMIFS('Corporate activity'!$H:$H,'Corporate activity'!$D:$D,Formulas!$L56,'Corporate activity'!$C:$C,Formulas!N$2) -> 0 | O56: =SUMIFS('Corporate activity'!$H:$H,'Corporate activity'!$D:$D,Formulas!$L56,'Corporate activity'!$C:$C,Formulas!O$2) -> 0 | P56: =SUM(M56:O56) -> 0 | Q56: =IF(OR(L56="",L56=0,P56=0),"",IF(COUNTIFS($P$3:$P$500,"<"&P56,$P$3:$P$500,"<>0")+1<=20,COUNTIFS($P$3:$P$500,"<"&P56,$P$3:$P$500,"<>0")+1,""))
C57: =SUMIFS(Issuance!$H:$H,Issuance!$D:$D,Formulas!$B57,Issuance!$C:$C,Formulas!C$2) -> 0 | D57: =SUMIFS(Issuance!$H:$H,Issuance!$D:$D,Formulas!$B57,Issuance!$C:$C,Formulas!D$2) -> 0 | E57: =SUM(C57:D57) -> 0 | F57: =IF(OR(B57="",B57=0,E57=0),"",IF(COUNTIFS($E$3:$E$500,">"&E57,$E$3:$E$500,"<>0")+1<=20,COUNTIFS($E$3:$E$500,">"&E57,$E$3:$E$500,"<>0")+1,"")) | H57: JPMorgan US Smaller Companies | I57: =SUMIFS(Buybacks!H:H,Buybacks!D:D,Formulas!H57) -> -19.967124 | J57: =IF(OR(H57="",H57=0,I57=0),"",IF(COUNTIFS($I$3:$I$500,"<"&I57,$I$3:$I$500,"<>0")+1<=20,COUNTIFS($I$3:$I$500,"<"&I57,$I$3:$I$500,"<>0")+1,"")) | L57: Life Science REIT | M57: =SUMIFS('Corporate activity'!$H:$H,'Corporate activity'!$D:$D,Formulas!$L57,'Corporate activity'!$C:$C,Formulas!M$2) -> 0 | N57: =SUMIFS('Corporate activity'!$H:$H,'Corporate activity'!$D:$D,Formulas!$L57,'Corporate activity'!$C:$C,Formulas!N$2) -> 0 | O57: =SUMIFS('Corporate activity'!$H:$H,'Corporate activity'!$D:$D,Formulas!$L57,'Corporate activity'!$C:$C,Formulas!O$2) -> 0 | P57: =SUM(M57:O57) -> 0 | Q57: =IF(OR(L57="",L57=0,P57=0),"",IF(COUNTIFS($P$3:$P$500,"<"&P57,$P$3:$P$500,"<>0")+1<=20,COUNTIFS($P$3:$P$500,"<"&P57,$P$3:$P$500,"<>0")+1,""))
C58: =SUMIFS(Issuance!$H:$H,Issuance!$D:$D,Formulas!$B58,Issuance!$C:$C,Formulas!C$2) -> 0 | D58: =SUMIFS(Issuance!$H:$H,Issuance!$D:$D,Formulas!$B58,Issuance!$C:$C,Formulas!D$2) -> 0 | E58: =SUM(C58:D58) -> 0 | F58: =IF(OR(B58="",B58=0,E58=0),"",IF(COUNTIFS($E$3:$E$500,">"&E58,$E$3:$E$500,"<>0")+1<=20,COUNTIFS($E$3:$E$500,">"&E58,$E$3:$E$500,"<>0")+1,"")) | H58: Mercantile Investment Trust | I58: =SUMIFS(Buybacks!H:H,Buybacks!D:D,Formulas!H58) -> -145.3855 | J58: =IF(OR(H58="",H58=0,I58=0),"",IF(COUNTIFS($I$3:$I$500,"<"&I58,$I$3:$I$500,"<>0")+1<=20,COUNTIFS($I$3:$I$500,"<"&I58,$I$3:$I$500,"<>0")+1,"")) -> 6 | L58: CVC Income & Growth | M58: =SUMIFS('Corporate activity'!$H:$H,'Corporate activity'!$D:$D,Formulas!$L58,'Corporate activity'!$C:$C,Formulas!M$2) -> -0.033264 | N58: =SUMIFS('Corporate activity'!$H:$H,'Corporate activity'!$D:$D,Formulas!$L58,'Corporate activity'!$C:$C,Formulas!N$2) -> 0 | O58: =SUMIFS('Corporate activity'!$H:$H,'Corporate activity'!$D:$D,Formulas!$L58,'Corporate activity'!$C:$C,Formulas!O$2) -> 0 | P58: =SUM(M58:O58) -> -0.033264 | Q58: =IF(OR(L58="",L58=0,P58=0),"",IF(COUNTIFS($P$3:$P$500,"<"&P58,$P$3:$P$500,"<>0")+1<=20,COUNTIFS($P$3:$P$500,"<"&P58,$P$3:$P$500,"<>0")+1,""))
C59: =SUMIFS(Issuance!$H:$H,Issuance!$D:$D,Formulas!$B59,Issuance!$C:$C,Formulas!C$2) -> 0 | D59: =SUMIFS(Issuance!$H:$H,Issuance!$D:$D,Formulas!$B59,Issuance!$C:$C,Formulas!D$2) -> 0 | E59: =SUM(C59:D59) -> 0 | F59: =IF(OR(B59="",B59=0,E59=0),"",IF(COUNTIFS($E$3:$E$500,">"&E59,$E$3:$E$500,"<>0")+1<=20,COUNTIFS($E$3:$E$500,">"&E59,$E$3:$E$500,"<>0")+1,"")) | H59: Mid Wynd International | I59: =SUMIFS(Buybacks!H:H,Buybacks!D:D,Formulas!H59) -> -43.485891 | J59: =IF(OR(H59="",H59=0,I59=0),"",IF(COUNTIFS($I$3:$I$500,"<"&I59,$I$3:$I$500,"<>0")+1<=20,COUNTIFS($I$3:$I$500,"<"&I59,$I$3:$I$500,"<>0")+1,"")) | L59: Tetragon Financial Group | M59: =SUMIFS('Corporate activity'!$H:$H,'Corporate activity'!$D:$D,Formulas!$L59,'Corporate activity'!$C:$C,Formulas!M$2) -> -36.888 | N59: =SUMIFS('Corporate activity'!$H:$H,'Corporate activity'!$D:$D,Formulas!$L59,'Corporate activity'!$C:$C,Formulas!N$2) -> 0 | O59: =SUMIFS('Corporate activity'!$H:$H,'Corporate activity'!$D:$D,Formulas!$L59,'Corporate activity'!$C:$C,Formulas!O$2) -> 0 | P59: =SUM(M59:O59) -> -36.888 | Q59: =IF(OR(L59="",L59=0,P59=0),"",IF(COUNTIFS($P$3:$P$500,"<"&P59,$P$3:$P$500,"<>0")+1<=20,COUNTIFS($P$3:$P$500,"<"&P59,$P$3:$P$500,"<>0")+1,"")) -> 14
C60: =SUMIFS(Issuance!$H:$H,Issuance!$D:$D,Formulas!$B60,Issuance!$C:$C,Formulas!C$2) -> 0 | D60: =SUMIFS(Issuance!$H:$H,Issuance!$D:$D,Formulas!$B60,Issuance!$C:$C,Formulas!D$2) -> 0 | E60: =SUM(C60:D60) -> 0 | F60: =IF(OR(B60="",B60=0,E60=0),"",IF(COUNTIFS($E$3:$E$500,">"&E60,$E$3:$E$500,"<>0")+1<=20,COUNTIFS($E$3:$E$500,">"&E60,$E$3:$E$500,"<>0")+1,"")) | H60: MIGO Opportunities Trust | I60: =SUMIFS(Buybacks!H:H,Buybacks!D:D,Formulas!H60) -> -2.0076496 | J60: =IF(OR(H60="",H60=0,I60=0),"",IF(COUNTIFS($I$3:$I$500,"<"&I60,$I$3:$I$500,"<>0")+1<=20,COUNTIFS($I$3:$I$500,"<"&I60,$I$3:$I$500,"<>0")+1,"")) | L60: Home REIT | M60: =SUMIFS('Corporate activity'!$H:$H,'Corporate activity'!$D:$D,Formulas!$L60,'Corporate activity'!$C:$C,Formulas!M$2) -> 0 | N60: =SUMIFS('Corporate activity'!$H:$H,'Corporate activity'!$D:$D,Formulas!$L60,'Corporate activity'!$C:$C,Formulas!N$2) -> 0 | O60: =SUMIFS('Corporate activity'!$H:$H,'Corporate activity'!$D:$D,Formulas!$L60,'Corporate activity'!$C:$C,Formulas!O$2) -> 0 | P60: =SUM(M60:O60) -> 0 | Q60: =IF(OR(L60="",L60=0,P60=0),"",IF(COUNTIFS($P$3:$P$500,"<"&P60,$P$3:$P$500,"<>0")+1<=20,COUNTIFS($P$3:$P$500,"<"&P60,$P$3:$P$500,"<>0")+1,""))
C61: =SUMIFS(Issuance!$H:$H,Issuance!$D:$D,Formulas!$B61,Issuance!$C:$C,Formulas!C$2) -> 0 | D61: =SUMIFS(Issuance!$H:$H,Issuance!$D:$D,Formulas!$B61,Issuance!$C:$C,Formulas!D$2) -> 0 | E61: =SUM(C61:D61) -> 0 | F61: =IF(OR(B61="",B61=0,E61=0),"",IF(COUNTIFS($E$3:$E$500,">"&E61,$E$3:$E$500,"<>0")+1<=20,COUNTIFS($E$3:$E$500,">"&E61,$E$3:$E$500,"<>0")+1,"")) | H61: Molten Ventures | I61: =SUMIFS(Buybacks!H:H,Buybacks!D:D,Formulas!H61) -> -12.413618 | J61: =IF(OR(H61="",H61=0,I61=0),"",IF(COUNTIFS($I$3:$I$500,"<"&I61,$I$3:$I$500,"<>0")+1<=20,COUNTIFS($I$3:$I$500,"<"&I61,$I$3:$I$500,"<>0")+1,"")) | L61: Biotech Growth Trust | M61: =SUMIFS('Corporate activity'!$H:$H,'Corporate activity'!$D:$D,Formulas!$L61,'Corporate activity'!$C:$C,Formulas!M$2) -> 0 | N61: =SUMIFS('Corporate activity'!$H:$H,'Corporate activity'!$D:$D,Formulas!$L61,'Corporate activity'!$C:$C,Formulas!N$2) -> 0 | O61: =SUMIFS('Corporate activity'!$H:$H,'Corporate activity'!$D:$D,Formulas!$L61,'Corporate activity'!$C:$C,Formulas!O$2) -> 0 | P61: =SUM(M61:O61) -> 0 | Q61: =IF(OR(L61="",L61=0,P61=0),"",IF(COUNTIFS($P$3:$P$500,"<"&P61,$P$3:$P$500,"<>0")+1<=20,COUNTIFS($P$3:$P$500,"<"&P61,$P$3:$P$500,"<>0")+1,""))
C62: =SUMIFS(Issuance!$H:$H,Issuance!$D:$D,Formulas!$B62,Issuance!$C:$C,Formulas!C$2) -> 0 | D62: =SUMIFS(Issuance!$H:$H,Issuance!$D:$D,Formulas!$B62,Issuance!$C:$C,Formulas!D$2) -> 0 | E62: =SUM(C62:D62) -> 0 | F62: =IF(OR(B62="",B62=0,E62=0),"",IF(COUNTIFS($E$3:$E$500,">"&E62,$E$3:$E$500,"<>0")+1<=20,COUNTIFS($E$3:$E$500,">"&E62,$E$3:$E$500,"<>0")+1,"")) | H62: Monks | I62: =SUMIFS(Buybacks!H:H,Buybacks!D:D,Formulas!H62) -> -156.71252 | J62: =IF(OR(H62="",H62=0,I62=0),"",IF(COUNTIFS($I$3:$I$500,"<"&I62,$I$3:$I$500,"<>0")+1<=20,COUNTIFS($I$3:$I$500,"<"&I62,$I$3:$I$500,"<>0")+1,"")) -> 5 | L62: International Biotechnology | M62: =SUMIFS('Corporate activity'!$H:$H,'Corporate activity'!$D:$D,Formulas!$L62,'Corporate activity'!$C:$C,Formulas!M$2) -> 0 | N62: =SUMIFS('Corporate activity'!$H:$H,'Corporate activity'!$D:$D,Formulas!$L62,'Corporate activity'!$C:$C,Formulas!N$2) -> 0 | O62: =SUMIFS('Corporate activity'!$H:$H,'Corporate activity'!$D:$D,Formulas!$L62,'Corporate activity'!$C:$C,Formulas!O$2) -> 0 | P62: =SUM(M62:O62) -> 0 | Q62: =IF(OR(L62="",L62=0,P62=0),"",IF(COUNTIFS($P$3:$P$500,"<"&P62,$P$3:$P$500,"<>0")+1<=20,COUNTIFS($P$3:$P$500,"<"&P62,$P$3:$P$500,"<>0")+1,""))
... C113: =SUMIFS(Issuance!$H:$H,Issuance!$D:$D,Formulas!$B113,Issuance!$C:$C,Formulas!C$2) -> 0 | D113: =SUMIFS(Issuance!$H:$H,Issuance!$D:$D,Formulas!$B113,Issuance!$C:$C,Formulas!D$2) -> 0 | E113: =SUM(C113:D113) -> 0 | F113: =IF(OR(B113="",B113=0,E113=0),"",IF(COUNTIFS($E$3:$E$500,">"&E113,$E$3:$E$500,"<>0")+1<=20,COUNTIFS($E$3:$E$500,">"&E113,$E$3:$E$500,"<>0")+1,"")) | H113: JPMorgan UK Small Cap Growth & Income | I113: =SUMIFS(Buybacks!H:H,Buybacks!D:D,Formulas!H113) -> -13.905853 | J113: =IF(OR(H113="",H113=0,I113=0),"",IF(COUNTIFS($I$3:$I$500,"<"&I113,$I$3:$I$500,"<>0")+1<=20,COUNTIFS($I$3:$I$500,"<"&I113,$I$3:$I$500,"<>0")+1,"")) | L113: NextEnergy Solar | M113: =SUMIFS('Corporate activity'!$H:$H,'Corporate activity'!$D:$D,Formulas!$L113,'Corporate activity'!$C:$C,Formulas!M$2) -> 0 | N113: =SUMIFS('Corporate activity'!$H:$H,'Corporate activity'!$D:$D,Formulas!$L113,'Corporate activity'!$C:$C,Formulas!N$2) -> 0 | O113: =SUMIFS('Corporate activity'!$H:$H,'Corporate activity'!$D:$D,Formulas!$L113,'Corporate activity'!$C:$C,Formulas!O$2) -> 0 | P113: =SUM(M113:O113) -> 0 | Q113: =IF(OR(L113="",L113=0,P113=0),"",IF(COUNTIFS($P$3:$P$500,"<"&P113,$P$3:$P$500,"<>0")+1<=20,COUNTIFS($P$3:$P$500,"<"&P113,$P$3:$P$500,"<>0")+1,""))
C114: =SUMIFS(Issuance!$H:$H,Issuance!$D:$D,Formulas!$B114,Issuance!$C:$C,Formulas!C$2) -> 0 | D114: =SUMIFS(Issuance!$H:$H,Issuance!$D:$D,Formulas!$B114,Issuance!$C:$C,Formulas!D$2) -> 0 | E114: =SUM(C114:D114) -> 0 | F114: =IF(OR(B114="",B114=0,E114=0),"",IF(COUNTIFS($E$3:$E$500,">"&E114,$E$3:$E$500,"<>0")+1<=20,COUNTIFS($E$3:$E$500,">"&E114,$E$3:$E$500,"<>0")+1,"")) | H114: Life Settlement Assets | I114: =SUMIFS(Buybacks!H:H,Buybacks!D:D,Formulas!H114) -> -3.7889855 | J114: =IF(OR(H114="",H114=0,I114=0),"",IF(COUNTIFS($I$3:$I$500,"<"&I114,$I$3:$I$500,"<>0")+1<=20,COUNTIFS($I$3:$I$500,"<"&I114,$I$3:$I$500,"<>0")+1,"")) | L114: 0 | M114: =SUMIFS('Corporate activity'!$H:$H,'Corporate activity'!$D:$D,Formulas!$L114,'Corporate activity'!$C:$C,Formulas!M$2) -> 0 | N114: =SUMIFS('Corporate activity'!$H:$H,'Corporate activity'!$D:$D,Formulas!$L114,'Corporate activity'!$C:$C,Formulas!N$2) -> 0 | O114: =SUMIFS('Corporate activity'!$H:$H,'Corporate activity'!$D:$D,Formulas!$L114,'Corporate activity'!$C:$C,Formulas!O$2) -> 0 | P114: =SUM(M114:O114) -> 0 | Q114: =IF(OR(L114="",L114=0,P114=0),"",IF(COUNTIFS($P$3:$P$500,"<"&P114,$P$3:$P$500,"<>0")+1<=20,COUNTIFS($P$3:$P$500,"<"&P114,$P$3:$P$500,"<>0")+1,""))
C115: =SUMIFS(Issuance!$H:$H,Issuance!$D:$D,Formulas!$B115,Issuance!$C:$C,Formulas!C$2) -> 0 | D115: =SUMIFS(Issuance!$H:$H,Issuance!$D:$D,Formulas!$B115,Issuance!$C:$C,Formulas!D$2) -> 0 | E115: =SUM(C115:D115) -> 0 | F115: =IF(OR(B115="",B115=0,E115=0),"",IF(COUNTIFS($E$3:$E$500,">"&E115,$E$3:$E$500,"<>0")+1<=20,COUNTIFS($E$3:$E$500,">"&E115,$E$3:$E$500,"<>0")+1,"")) | H115: M&G Credit Income | I115: =SUMIFS(Buybacks!H:H,Buybacks!D:D,Formulas!H115) -> -0.2230025 | J115: =IF(OR(H115="",H115=0,I115=0),"",IF(COUNTIFS($I$3:$I$500,"<"&I115,$I$3:$I$500,"<>0")+1<=20,COUNTIFS($I$3:$I$500,"<"&I115,$I$3:$I$500,"<>0")+1,"")) | M115: =SUMIFS('Corporate activity'!$H:$H,'Corporate activity'!$D:$D,Formulas!$L115,'Corporate activity'!$C:$C,Formulas!M$2) -> 0 | N115: =SUMIFS('Corporate activity'!$H:$H,'Corporate activity'!$D:$D,Formulas!$L115,'Corporate activity'!$C:$C,Formulas!N$2) -> 0 | O115: =SUMIFS('Corporate activity'!$H:$H,'Corporate activity'!$D:$D,Formulas!$L115,'Corporate activity'!$C:$C,Formulas!O$2) -> 0 | P115: =SUM(M115:O115) -> 0 | Q115: =IF(OR(L115="",L115=0,P115=0),"",IF(COUNTIFS($P$3:$P$500,"<"&P115,$P$3:$P$500,"<>0")+1<=20,COUNTIFS($P$3:$P$500,"<"&P115,$P$3:$P$500,"<>0")+1,""))
C116: =SUMIFS(Issuance!$H:$H,Issuance!$D:$D,Formulas!$B116,Issuance!$C:$C,Formulas!C$2) -> 0 | D116: =SUMIFS(Issuance!$H:$H,Issuance!$D:$D,Formulas!$B116,Issuance!$C:$C,Formulas!D$2) -> 0 | E116: =SUM(C116:D116) -> 0 | F116: =IF(OR(B116="",B116=0,E116=0),"",IF(COUNTIFS($E$3:$E$500,">"&E116,$E$3:$E$500,"<>0")+1<=20,COUNTIFS($E$3:$E$500,">"&E116,$E$3:$E$500,"<>0")+1,"")) | H116: Montanaro UK Smaller Companies | I116: =SUMIFS(Buybacks!H:H,Buybacks!D:D,Formulas!H116) -> -5.3833052 | J116: =IF(OR(H116="",H116=0,I116=0),"",IF(COUNTIFS($I$3:$I$500,"<"&I116,$I$3:$I$500,"<>0")+1<=20,COUNTIFS($I$3:$I$500,"<"&I116,$I$3:$I$500,"<>0")+1,"")) | M116: =SUMIFS('Corporate activity'!$H:$H,'Corporate activity'!$D:$D,Formulas!$L116,'Corporate activity'!$C:$C,Formulas!M$2) -> 0 | N116: =SUMIFS('Corporate activity'!$H:$H,'Corporate activity'!$D:$D,Formulas!$L116,'Corporate activity'!$C:$C,Formulas!N$2) -> 0 | O116: =SUMIFS('Corporate activity'!$H:$H,'Corporate activity'!$D:$D,Formulas!$L116,'Corporate activity'!$C:$C,Formulas!O$2) -> 0 | P116: =SUM(M116:O116) -> 0 | Q116: =IF(OR(L116="",L116=0,P116=0),"",IF(COUNTIFS($P$3:$P$500,"<"&P116,$P$3:$P$500,"<>0")+1<=20,COUNTIFS($P$3:$P$500,"<"&P116,$P$3:$P$500,"<>0")+1,""))
C117: =SUMIFS(Issuance!$H:$H,Issuance!$D:$D,Formulas!$B117,Issuance!$C:$C,Formulas!C$2) -> 0 | D117: =SUMIFS(Issuance!$H:$H,Issuance!$D:$D,Formulas!$B117,Issuance!$C:$C,Formulas!D$2) -> 0 | E117: =SUM(C117:D117) -> 0 | F117: =IF(OR(B117="",B117=0,E117=0),"",IF(COUNTIFS($E$3:$E$500,">"&E117,$E$3:$E$500,"<>0")+1<=20,COUNTIFS($E$3:$E$500,">"&E117,$E$3:$E$500,"<>0")+1,"")) | H117: North American Income Trust | I117: =SUMIFS(Buybacks!H:H,Buybacks!D:D,Formulas!H117) -> -0.19755984 | J117: =IF(OR(H117="",H117=0,I117=0),"",IF(COUNTIFS($I$3:$I$500,"<"&I117,$I$3:$I$500,"<>0")+1<=20,COUNTIFS($I$3:$I$500,"<"&I117,$I$3:$I$500,"<>0")+1,"")) | M117: =SUMIFS('Corporate activity'!$H:$H,'Corporate activity'!$D:$D,Formulas!$L117,'Corporate activity'!$C:$C,Formulas!M$2) -> 0 | N117: =SUMIFS('Corporate activity'!$H:$H,'Corporate activity'!$D:$D,Formulas!$L117,'Corporate activity'!$C:$C,Formulas!N$2) -> 0 | O117: =SUMIFS('Corporate activity'!$H:$H,'Corporate activity'!$D:$D,Formulas!$L117,'Corporate activity'!$C:$C,Formulas!O$2) -> 0 | P117: =SUM(M117:O117) -> 0 | Q117: =IF(OR(L117="",L117=0,P117=0),"",IF(COUNTIFS($P$3:$P$500,"<"&P117,$P$3:$P$500,"<>0")+1<=20,COUNTIFS($P$3:$P$500,"<"&P117,$P$3:$P$500,"<>0")+1,""))
C118: =SUMIFS(Issuance!$H:$H,Issuance!$D:$D,Formulas!$B118,Issuance!$C:$C,Formulas!C$2) -> 0 | D118: =SUMIFS(Issuance!$H:$H,Issuance!$D:$D,Formulas!$B118,Issuance!$C:$C,Formulas!D$2) -> 0 | E118: =SUM(C118:D118) -> 0 | F118: =IF(OR(B118="",B118=0,E118=0),"",IF(COUNTIFS($E$3:$E$500,">"&E118,$E$3:$E$500,"<>0")+1<=20,COUNTIFS($E$3:$E$500,">"&E118,$E$3:$E$500,"<>0")+1,"")) | H118: Personal Assets Trust | I118: =SUMIFS(Buybacks!H:H,Buybacks!D:D,Formulas!H118) -> -40.194673 | J118: =IF(OR(H118="",H118=0,I118=0),"",IF(COUNTIFS($I$3:$I$500,"<"&I118,$I$3:$I$500,"<>0")+1<=20,COUNTIFS($I$3:$I$500,"<"&I118,$I$3:$I$500,"<>0")+1,"")) | M118: =SUMIFS('Corporate activity'!$H:$H,'Corporate activity'!$D:$D,Formulas!$L118,'Corporate activity'!$C:$C,Formulas!M$2) -> 0 | N118: =SUMIFS('Corporate activity'!$H:$H,'Corporate activity'!$D:$D,Formulas!$L118,'Corporate activity'!$C:$C,Formulas!N$2) -> 0 | O118: =SUMIFS('Corporate activity'!$H:$H,'Corporate activity'!$D:$D,Formulas!$L118,'Corporate activity'!$C:$C,Formulas!O$2) -> 0 | P118: =SUM(M118:O118) -> 0 | Q118: =IF(OR(L118="",L118=0,P118=0),"",IF(COUNTIFS($P$3:$P$500,"<"&P118,$P$3:$P$500,"<>0")+1<=20,COUNTIFS($P$3:$P$500,"<"&P118,$P$3:$P$500,"<>0")+1,""))
C119: =SUMIFS(Issuance!$H:$H,Issuance!$D:$D,Formulas!$B119,Issuance!$C:$C,Formulas!C$2) -> 0 | D119: =SUMIFS(Issuance!$H:$H,Issuance!$D:$D,Formulas!$B119,Issuance!$C:$C,Formulas!D$2) -> 0 | E119: =SUM(C119:D119) -> 0 | F119: =IF(OR(B119="",B119=0,E119=0),"",IF(COUNTIFS($E$3:$E$500,">"&E119,$E$3:$E$500,"<>0")+1<=20,COUNTIFS($E$3:$E$500,">"&E119,$E$3:$E$500,"<>0")+1,"")) | H119: Polar Capital Global Financials | I119: =SUMIFS(Buybacks!H:H,Buybacks!D:D,Formulas!H119) -> -12.386149 | J119: =IF(OR(H119="",H119=0,I119=0),"",IF(COUNTIFS($I$3:$I$500,"<"&I119,$I$3:$I$500,"<>0")+1<=20,COUNTIFS($I$3:$I$500,"<"&I119,$I$3:$I$500,"<>0")+1,"")) | M119: =SUMIFS('Corporate activity'!$H:$H,'Corporate activity'!$D:$D,Formulas!$L119,'Corporate activity'!$C:$C,Formulas!M$2) -> 0 | N119: =SUMIFS('Corporate activity'!$H:$H,'Corporate activity'!$D:$D,Formulas!$L119,'Corporate activity'!$C:$C,Formulas!N$2) -> 0 | O119: =SUMIFS('Corporate activity'!$H:$H,'Corporate activity'!$D:$D,Formulas!$L119,'Corporate activity'!$C:$C,Formulas!O$2) -> 0 | P119: =SUM(M119:O119) -> 0 | Q119: =IF(OR(L119="",L119=0,P119=0),"",IF(COUNTIFS($P$3:$P$500,"<"&P119,$P$3:$P$500,"<>0")+1<=20,COUNTIFS($P$3:$P$500,"<"&P119,$P$3:$P$500,"<>0")+1,""))
C120: =SUMIFS(Issuance!$H:$H,Issuance!$D:$D,Formulas!$B120,Issuance!$C:$C,Formulas!C$2) -> 0 | D120: =SUMIFS(Issuance!$H:$H,Issuance!$D:$D,Formulas!$B120,Issuance!$C:$C,Formulas!D$2) -> 0 | E120: =SUM(C120:D120) -> 0 | F120: =IF(OR(B120="",B120=0,E120=0),"",IF(COUNTIFS($E$3:$E$500,">"&E120,$E$3:$E$500,"<>0")+1<=20,COUNTIFS($E$3:$E$500,">"&E120,$E$3:$E$500,"<>0")+1,"")) | H120: Real Estate Credit Investments | I120: =SUMIFS(Buybacks!H:H,Buybacks!D:D,Formulas!H120) -> -0.82075 | J120: =IF(OR(H120="",H120=0,I120=0),"",IF(COUNTIFS($I$3:$I$500,"<"&I120,$I$3:$I$500,"<>0")+1<=20,COUNTIFS($I$3:$I$500,"<"&I120,$I$3:$I$500,"<>0")+1,"")) | M120: =SUMIFS('Corporate activity'!$H:$H,'Corporate activity'!$D:$D,Formulas!$L120,'Corporate activity'!$C:$C,Formulas!M$2) -> 0 | N120: =SUMIFS('Corporate activity'!$H:$H,'Corporate activity'!$D:$D,Formulas!$L120,'Corporate activity'!$C:$C,Formulas!N$2) -> 0 | O120: =SUMIFS('Corporate activity'!$H:$H,'Corporate activity'!$D:$D,Formulas!$L120,'Corporate activity'!$C:$C,Formulas!O$2) -> 0 | P120: =SUM(M120:O120) -> 0 | Q120: =IF(OR(L120="",L120=0,P120=0),"",IF(COUNTIFS($P$3:$P$500,"<"&P120,$P$3:$P$500,"<>0")+1<=20,COUNTIFS($P$3:$P$500,"<"&P120,$P$3:$P$500,"<>0")+1,""))
C121: =SUMIFS(Issuance!$H:$H,Issuance!$D:$D,Formulas!$B121,Issuance!$C:$C,Formulas!C$2) -> 0 | D121: =SUMIFS(Issuance!$H:$H,Issuance!$D:$D,Formulas!$B121,Issuance!$C:$C,Formulas!D$2) -> 0 | E121: =SUM(C121:D121) -> 0 | F121: =IF(OR(B121="",B121=0,E121=0),"",IF(COUNTIFS($E$3:$E$500,">"&E121,$E$3:$E$500,"<>0")+1<=20,COUNTIFS($E$3:$E$500,">"&E121,$E$3:$E$500,"<>0")+1,"")) | H121: RTW Biotech Opportunities | I121: =SUMIFS(Buybacks!H:H,Buybacks!D:D,Formulas!H121) -> -6.4663945 | J121: =IF(OR(H121="",H121=0,I121=0),"",IF(COUNTIFS($I$3:$I$500,"<"&I121,$I$3:$I$500,"<>0")+1<=20,COUNTIFS($I$3:$I$500,"<"&I121,$I$3:$I$500,"<>0")+1,"")) | M121: =SUMIFS('Corporate activity'!$H:$H,'Corporate activity'!$D:$D,Formulas!$L121,'Corporate activity'!$C:$C,Formulas!M$2) -> 0 | N121: =SUMIFS('Corporate activity'!$H:$H,'Corporate activity'!$D:$D,Formulas!$L121,'Corporate activity'!$C:$C,Formulas!N$2) -> 0 | O121: =SUMIFS('Corporate activity'!$H:$H,'Corporate activity'!$D:$D,Formulas!$L121,'Corporate activity'!$C:$C,Formulas!O$2) -> 0 | P121: =SUM(M121:O121) -> 0 | Q121: =IF(OR(L121="",L121=0,P121=0),"",IF(COUNTIFS($P$3:$P$500,"<"&P121,$P$3:$P$500,"<>0")+1<=20,COUNTIFS($P$3:$P$500,"<"&P121,$P$3:$P$500,"<>0")+1,""))
C122: =SUMIFS(Issuance!$H:$H,Issuance!$D:$D,Formulas!$B122,Issuance!$C:$C,Formulas!C$2) -> 0 | D122: =SUMIFS(Issuance!$H:$H,Issuance!$D:$D,Formulas!$B122,Issuance!$C:$C,Formulas!D$2) -> 0 | E122: =SUM(C122:D122) -> 0 | F122: =IF(OR(B122="",B122=0,E122=0),"",IF(COUNTIFS($E$3:$E$500,">"&E122,$E$3:$E$500,"<>0")+1<=20,COUNTIFS($E$3:$E$500,">"&E122,$E$3:$E$500,"<>0")+1,"")) | H122: Schroder Japan Trust | I122: =SUMIFS(Buybacks!H:H,Buybacks!D:D,Formulas!H122) -> -2.40552 | J122: =IF(OR(H122="",H122=0,I122=0),"",IF(COUNTIFS($I$3:$I$500,"<"&I122,$I$3:$I$500,"<>0")+1<=20,COUNTIFS($I$3:$I$500,"<"&I122,$I$3:$I$500,"<>0")+1,"")) | M122: =SUMIFS('Corporate activity'!$H:$H,'Corporate activity'!$D:$D,Formulas!$L122,'Corporate activity'!$C:$C,Formulas!M$2) -> 0 | N122: =SUMIFS('Corporate activity'!$H:$H,'Corporate activity'!$D:$D,Formulas!$L122,'Corporate activity'!$C:$C,Formulas!N$2) -> 0 | O122: =SUMIFS('Corporate activity'!$H:$H,'Corporate activity'!$D:$D,Formulas!$L122,'Corporate activity'!$C:$C,Formulas!O$2) -> 0 | P122: =SUM(M122:O122) -> 0 | Q122: =IF(OR(L122="",L122=0,P122=0),"",IF(COUNTIFS($P$3:$P$500,"<"&P122,$P$3:$P$500,"<>0")+1<=20,COUNTIFS($P$3:$P$500,"<"&P122,$P$3:$P$500,"<>0")+1,""))
C123: =SUMIFS(Issuance!$H:$H,Issuance!$D:$D,Formulas!$B123,Issuance!$C:$C,Formulas!C$2) -> 0 | D123: =SUMIFS(Issuance!$H:$H,Issuance!$D:$D,Formulas!$B123,Issuance!$C:$C,Formulas!D$2) -> 0 | E123: =SUM(C123:D123) -> 0 | F123: =IF(OR(B123="",B123=0,E123=0),"",IF(COUNTIFS($E$3:$E$500,">"&E123,$E$3:$E$500,"<>0")+1<=20,COUNTIFS($E$3:$E$500,">"&E123,$E$3:$E$500,"<>0")+1,"")) | H123: Value and Indexed Property Income Trust | I123: =SUMIFS(Buybacks!H:H,Buybacks!D:D,Formulas!H123) -> -0.9817 | J123: =IF(OR(H123="",H123=0,I123=0),"",IF(COUNTIFS($I$3:$I$500,"<"&I123,$I$3:$I$500,"<>0")+1<=20,COUNTIFS($I$3:$I$500,"<"&I123,$I$3:$I$500,"<>0")+1,"")) | M123: =SUMIFS('Corporate activity'!$H:$H,'Corporate activity'!$D:$D,Formulas!$L123,'Corporate activity'!$C:$C,Formulas!M$2) -> 0 | N123: =SUMIFS('Corporate activity'!$H:$H,'Corporate activity'!$D:$D,Formulas!$L123,'Corporate activity'!$C:$C,Formulas!N$2) -> 0 | O123: =SUMIFS('Corporate activity'!$H:$H,'Corporate activity'!$D:$D,Formulas!$L123,'Corporate activity'!$C:$C,Formulas!O$2) -> 0 | P123: =SUM(M123:O123) -> 0 | Q123: =IF(OR(L123="",L123=0,P123=0),"",IF(COUNTIFS($P$3:$P$500,"<"&P123,$P$3:$P$500,"<>0")+1<=20,COUNTIFS($P$3:$P$500,"<"&P123,$P$3:$P$500,"<>0")+1,""))
C124: =SUMIFS(Issuance!$H:$H,Issuance!$D:$D,Formulas!$B124,Issuance!$C:$C,Formulas!C$2) -> 0 | D124: =SUMIFS(Issuance!$H:$H,Issuance!$D:$D,Formulas!$B124,Issuance!$C:$C,Formulas!D$2) -> 0 | E124: =SUM(C124:D124) -> 0 | F124: =IF(OR(B124="",B124=0,E124=0),"",IF(COUNTIFS($E$3:$E$500,">"&E124,$E$3:$E$500,"<>0")+1<=20,COUNTIFS($E$3:$E$500,">"&E124,$E$3:$E$500,"<>0")+1,"")) | H124: AVI Japan Opportunity Trust | I124: =SUMIFS(Buybacks!H:H,Buybacks!D:D,Formulas!H124) -> -0.565785 | J124: =IF(OR(H124="",H124=0,I124=0),"",IF(COUNTIFS($I$3:$I$500,"<"&I124,$I$3:$I$500,"<>0")+1<=20,COUNTIFS($I$3:$I$500,"<"&I124,$I$3:$I$500,"<>0")+1,"")) | M124: =SUMIFS('Corporate activity'!$H:$H,'Corporate activity'!$D:$D,Formulas!$L124,'Corporate activity'!$C:$C,Formulas!M$2) -> 0 | N124: =SUMIFS('Corporate activity'!$H:$H,'Corporate activity'!$D:$D,Formulas!$L124,'Corporate activity'!$C:$C,Formulas!N$2) -> 0 | O124: =SUMIFS('Corporate activity'!$H:$H,'Corporate activity'!$D:$D,Formulas!$L124,'Corporate activity'!$C:$C,Formulas!O$2) -> 0 | P124: =SUM(M124:O124) -> 0 | Q124: =IF(OR(L124="",L124=0,P124=0),"",IF(COUNTIFS($P$3:$P$500,"<"&P124,$P$3:$P$500,"<>0")+1<=20,COUNTIFS($P$3:$P$500,"<"&P124,$P$3:$P$500,"<>0")+1,""))
...

Sheet Summary
B1: Produced by theaic.co.uk, 1st August 2026. Please note that, whilst we endeavour to verify all data sources, the information contained is not guaranteed to be accurate and the AIC does not accept responsibility for any errors or omissions.
B2: Corporate activity 2026 YTD
B5: IPOs | C5: =SUMIF($B$16:$B$26,"New Issue",$C$16:$C$26) -> 0
B6: Issuance | C6: =SUM($C$17:$C$26)-C5 -> 1473.6761
B7: Buybacks | C7: =ABS(SUMIF($E$17:$E$26,"Buyback",$F$17:$F$26))*-1 -> -5022.2825
B8: Company departures | C8: =SUMIF(E17:E26,"*" & "depart" & "*",$F$17:$F$26)+SUMIF($E$17:$E$26,"*" & "merge" & "*",$F$17:$F$26) -> -5213.7461
B9: Tenders & redemptions | C9: =(SUM($F$17:$F$26))-SUM($C$7:$C$8) -> -3034.3349
B11: TA-(Roll+Bankd)
B16: Event type | C16: Total assets in (£m) | E16: Event type | F16: Total assets out (£m) | H16: Event type | I16: No. of occurrences | K16: VCT event type (by calendar year) | L16: Value (£m) YTD
B17: Issue (from treasury) | C17: =SUMIF(Issuance!C:C,B17,Issuance!H:H) -> 786.20972 | E17: Buyback | F17: =SUM(Buybacks!H:H) -> -5022.2825 | H17: Fee change | I17: =COUNTIF('Corporate activity'!C:C,Summary!H17) -> 23 | K17: Buyback | L17: =SUMIF(VCT!C:C,K17,VCT!Q:Q) -> -104.73905
B18: Issue | C18: =SUMIF(Issuance!C:C,B18,Issuance!H:H) -> 550.95767 | E18: Reconstruct/depart | F18: =IF( SUMIF('Corporate activity'!C:C,E18,'Corporate activity'!H:H)=0, "-",SUMIF('Corporate activity'!C:C,E18,'Corporate activity'!H:H) -SUMIF('Corporate activity'!C:C,E18,'Corporate activity'!I:I) -SUMIF('Corporate activity'!C:C,E18,'Corporate activity'!J:J)) -> -2314.2308 | H18: New management | I18: =COUNTIF('Corporate activity'!C:C,Summary!H18) -> 10 | K18: Tender offer | L18: =SUMIF(VCT!C:C,K18,VCT!Q:Q) -> -9.205706
B19: Issue (C share) | C19: =SUMIF(Issuance!C:C,B19,Issuance!H:H) -> 136.50866 | E19: Depart/liquidate | F19: =IF( SUMIF('Corporate activity'!C:C,E19,'Corporate activity'!H:H)=0, "-",SUMIF('Corporate activity'!C:C,E19,'Corporate activity'!H:H) -SUMIF('Corporate activity'!C:C,E19,'Corporate activity'!I:I) -SUMIF('Corporate activity'!C:C,E19,'Corporate activity'!J:J)) -> -2689.9735 | H19: Investment policy change | I19: =COUNTIF('Corporate activity'!C:C,"Policy change") -> 7
B20: IPO | C20: =SUMIF(Issuance!C:C,"New issue",'Corporate activity'!H:H) -> 0 | E20: Tender offer | F20: =IF(SUMIF('Corporate activity'!C:C,E20,'Corporate activity'!H:H)=0,"-",SUMIF('Corporate activity'!C:C,E20,'Corporate activity'!H:H)) -> -2730.7674 | H20: New name | I20: =COUNTIF('Corporate activity'!C:C,Summary!H20) -> 5 | K20: Tax year | L20: DRIS | M20: Fundraising | N20: Total
E21: Merger | F21: =IF( SUMIF('Corporate activity'!C:C,"Merge/depart",'Corporate activity'!H:H)=0, "-", SUMIF('Corporate activity'!C:C,"Merge/depart",'Corporate activity'!H:H) - SUMIF('Corporate activity'!C:C,"Merge/depart",'Corporate activity'!I:I) - SUMIF('Corporate activity'!C:C,"Merge/depart",'Corporate activity'!J:J)) -> -209.54183 | H21: Capital change | I21: =COUNTIF('Corporate activity'!C:C,Summary!H21) -> 4 | K21: 2025/26 | L21: 61 | M21: 857 | N21: =SUM(L21:M21) -> 918
E22: Capital redemption | F22: =IF(SUMIF('Corporate activity'!C:C,E22,'Corporate activity'!H:H)=0,"-",SUMIF('Corporate activity'!C:C,E22,'Corporate activity'!H:H)) -> -187.55053 | H22: Realisation policy | I22: =COUNTIF('Corporate activity'!C:C,Summary!H22) -> 4 | K22: 2026/27 to date | L22: =SUMIFS(VCT!Q:Q,VCT!N:N,"2026/27",VCT!C:C,"Issue (DRIS)") -> 16.92989 | M22: =SUMIFS(VCT!Q:Q,VCT!N:N,"2026/27",VCT!C:C,"Issue") -> 17.514842 | N22: =SUM(L22:M22) -> 34.444732
E23: Capital distribution | F23: =IF(SUMIF('Corporate activity'!C:C,E23,'Corporate activity'!H:H)=0,"-",SUMIF('Corporate activity'!C:C,E23,'Corporate activity'!H:H)) -> -116.01695 | H23: Listing change | I23: =COUNTIF('Corporate activity'!C:C,Summary!H23) -> 3
H24: Trading status | I24: =COUNTIF('Corporate activity'!C:C,Summary!H24) -> 3 | K24: No. of VCT offers | L24: Current
H25: AIC sector change | I25: =COUNTIF('Corporate activity'!C:C,Summary!H25) -> 2 | K25: Open | L25: =COUNTIF(VCT!C:C,"open offer for subscription") -> 11
H26: Domicile change | I26: =COUNTIF('Corporate activity'!C:C,Summary!H26) -> 1
A27: =MAX(Formulas!F:F) -> 20 | D27: =MAX(Formulas!J:J) -> 20 | G27: =MAX(Formulas!Q:Q) -> 20
A28: 0 | B28: Top 20 companies (Issuance) | C28: Issuance (£m) | D28: 0 | E28: Top 20 companies (Buybacks) | F28: Buybacks (£m) | G28: 0 | H28: Top 20 companies (Other tenders / redemptions) | I28: Other tenders / redemptions (£m) | K28: Company departures | L28: Departure month | M28: Assets at departure (£m)
A29: =IF(OR($A28="",$A28>$A$27-1),"",$A28+1) -> 1 | B29: =IF($A29="","",_xlfn.XLOOKUP($A29,Formulas!$F:$F,Formulas!$B:$B)) -> Scottish Mortgage | C29: =IF($A29="","",_xlfn.XLOOKUP($A29,Formulas!$F:$F,Formulas!$E:$E)) -> 519.08239 | D29: =IF(OR($D28="",$D28>$D$27-1),"",$D28+1) -> 1 | E29: =IF($D29="","",_xlfn.XLOOKUP($D29,Formulas!J:J,Formulas!H:H)) -> Scottish Mortgage | F29: =IF($D29="","",_xlfn.XLOOKUP($D29,Formulas!J:J,Formulas!I:I)) -> -796.68848 | G29: =IF(OR($G28="",$G28>$G$27-1),"",$G28+1) -> 1 | H29: =_xlfn.XLOOKUP(G29,Formulas!Q:Q,Formulas!L:L) -> Herald Investment Trust | I29: =_xlfn.XLOOKUP(G29,Formulas!Q:Q,Formulas!P:P) -> -957.35847 | K29: {=_xlfn.LET(_xlpm.events,'Corporate activity'!$C$4:$C$3000,_xlpm.companies,'Corporate activity'!$D$4:$D$3000,_xlpm.months,'Corporate activity'!$B$4:$B$3000,_xlpm.assets,'Corporate activity'!$H$4:$H$3000-'Corporate activity'!$I$4:$I$3000-'Corporate activity'!$J$4:$J$3000,_xlpm.status,'Corporate activity'!$A$4:$A$3000,_xlpm.include,ISNUMBER(SEARCH("depart",_xlpm.events))*(_xlpm.months<>"TBA")*ISERROR(SEARCH("await",_xlpm.status)),_xlpm.depart,_xlfn._xlws.FILTER(CHOOSE({1,2,3},_xlpm.companies,_xlpm.months,_xlpm.assets),_xlpm.include),_xlfn.UNIQUE(_xlpm.depart))} -> Doric Nimrod Air Three | L29: Jan | M29: -142.347
A30: =IF(OR($A29="",$A29>$A$27-1),"",$A29+1) -> 2 | B30: =IF($A30="","",_xlfn.XLOOKUP($A30,Formulas!$F:$F,Formulas!$B:$B)) -> TwentyFour Income Fund | C30: =IF($A30="","",_xlfn.XLOOKUP($A30,Formulas!$F:$F,Formulas!$E:$E)) -> 110.62046 | D30: =IF(OR($D29="",$D29>$D$27-1),"",$D29+1) -> 2 | E30: =IF($D30="","",_xlfn.XLOOKUP($D30,Formulas!J:J,Formulas!H:H)) -> 3i Group | F30: =IF($D30="","",_xlfn.XLOOKUP($D30,Formulas!J:J,Formulas!I:I)) -> -359.54513 | G30: =IF(OR($G29="",$G29>$G$27-1),"",$G29+1) -> 2 | H30: =_xlfn.XLOOKUP(G30,Formulas!Q:Q,Formulas!L:L) -> Impax Environmental Markets | I30: =_xlfn.XLOOKUP(G30,Formulas!Q:Q,Formulas!P:P) -> -733.2478 | K30: PRS REIT | L30: Jan | M30: -815.37143
A31: =IF(OR($A30="",$A30>$A$27-1),"",$A30+1) -> 3 | B31: =IF($A31="","",_xlfn.XLOOKUP($A31,Formulas!$F:$F,Formulas!$B:$B)) -> Invesco Bond Income Plus | C31: =IF($A31="","",_xlfn.XLOOKUP($A31,Formulas!$F:$F,Formulas!$E:$E)) -> 98.909156 | D31: =IF(OR($D30="",$D30>$D$27-1),"",$D30+1) -> 3 | E31: =IF($D31="","",_xlfn.XLOOKUP($D31,Formulas!J:J,Formulas!H:H)) -> Allianz Technology Trust | F31: =IF($D31="","",_xlfn.XLOOKUP($D31,Formulas!J:J,Formulas!I:I)) -> -160.62452 | G31: =IF(OR($G30="",$G30>$G$27-1),"",$G30+1) -> 3 | H31: =_xlfn.XLOOKUP(G31,Formulas!Q:Q,Formulas!L:L) -> RIT Capital Partners | I31: =_xlfn.XLOOKUP(G31,Formulas!Q:Q,Formulas!P:P) -> -299.99999 | K31: Starwood European Real Estate Finance | L31: Feb | M31: -22.36
A32: =IF(OR($A31="",$A31>$A$27-1),"",$A31+1) -> 4 | B32: =IF($A32="","",_xlfn.XLOOKUP($A32,Formulas!$F:$F,Formulas!$B:$B)) -> Henderson Far East Income | C32: =IF($A32="","",_xlfn.XLOOKUP($A32,Formulas!$F:$F,Formulas!$E:$E)) -> 90.027288 | D32: =IF(OR($D31="",$D31>$D$27-1),"",$D31+1) -> 4 | E32: =IF($D32="","",_xlfn.XLOOKUP($D32,Formulas!J:J,Formulas!H:H)) -> Pantheon International | F32: =IF($D32="","",_xlfn.XLOOKUP($D32,Formulas!J:J,Formulas!I:I)) -> -158.22095 | G32: =IF(OR($G31="",$G31>$G$27-1),"",$G31+1) -> 4 | H32: =_xlfn.XLOOKUP(G32,Formulas!Q:Q,Formulas!L:L) -> Vietnam Enterprise Investments | I32: =_xlfn.XLOOKUP(G32,Formulas!Q:Q,Formulas!P:P) -> -263.55335 | K32: Franklin Global Trust | L32: Feb | M32: -6.23117
A33: =IF(OR($A32="",$A32>$A$27-1),"",$A32+1) -> 5 | B33: =IF($A33="","",_xlfn.XLOOKUP($A33,Formulas!$F:$F,Formulas!$B:$B)) -> City of London Investment Trust | C33: =IF($A33="","",_xlfn.XLOOKUP($A33,Formulas!$F:$F,Formulas!$E:$E)) -> 63.3275 | D33: =IF(OR($D32="",$D32>$D$27-1),"",$D32+1) -> 5 | E33: =IF($D33="","",_xlfn.XLOOKUP($D33,Formulas!J:J,Formulas!H:H)) -> Monks | F33: =IF($D33="","",_xlfn.XLOOKUP($D33,Formulas!J:J,Formulas!I:I)) -> -156.71252 | G33: =IF(OR($G32="",$G32>$G$27-1),"",$G32+1) -> 5 | H33: =_xlfn.XLOOKUP(G33,Formulas!Q:Q,Formulas!L:L) -> BlackRock Smaller Companies | I33: =_xlfn.XLOOKUP(G33,Formulas!Q:Q,Formulas!P:P) -> -162.91717 | K33: Smithson | L33: Feb | M33: -1679
A34: =IF(OR($A33="",$A33>$A$27-1),"",$A33+1) -> 6 | B34: =IF($A34="","",_xlfn.XLOOKUP($A34,Formulas!$F:$F,Formulas!$B:$B)) -> Temple Bar Investment Trust | C34: =IF($A34="","",_xlfn.XLOOKUP($A34,Formulas!$F:$F,Formulas!$E:$E)) -> 59.647078 | D34: =IF(OR($D33="",$D33>$D$27-1),"",$D33+1) -> 6 | E34: =IF($D34="","",_xlfn.XLOOKUP($D34,Formulas!J:J,Formulas!H:H)) -> Mercantile Investment Trust | F34: =IF($D34="","",_xlfn.XLOOKUP($D34,Formulas!J:J,Formulas!I:I)) -> -145.3855 | G34: =IF(OR($G33="",$G33>$G$27-1),"",$G33+1) -> 6 | H34: =_xlfn.XLOOKUP(G34,Formulas!Q:Q,Formulas!L:L) -> Baillie Gifford Shin Nippon | I34: =_xlfn.XLOOKUP(G34,Formulas!Q:Q,Formulas!P:P) -> -57.755505 | K34: abrdn Diversified Income & Growth | L34: Mar | M34: -46.5
A35: =IF(OR($A34="",$A34>$A$27-1),"",$A34+1) -> 7 | B35: =IF($A35="","",_xlfn.XLOOKUP($A35,Formulas!$F:$F,Formulas!$B:$B)) -> CVC Income & Growth | C35: =IF($A35="","",_xlfn.XLOOKUP($A35,Formulas!$F:$F,Formulas!$E:$E)) -> 40.055654 | D35: =IF(OR($D34="",$D34>$D$27-1),"",$D34+1) -> 7 | E35: =IF($D35="","",_xlfn.XLOOKUP($D35,Formulas!J:J,Formulas!H:H)) -> Alliance Witan | F35: =IF($D35="","",_xlfn.XLOOKUP($D35,Formulas!J:J,Formulas!I:I)) -> -141.56233 | G35: =IF(OR($G34="",$G34>$G$27-1),"",$G34+1) -> 7 | H35: =_xlfn.XLOOKUP(G35,Formulas!Q:Q,Formulas!L:L) -> BlackRock Frontiers | I35: =_xlfn.XLOOKUP(G35,Formulas!Q:Q,Formulas!P:P) -> -48.139318 | K35: Shires Income | L35: Mar | M35: -14.279663
A36: =IF(OR($A35="",$A35>$A$27-1),"",$A35+1) -> 8 | B36: =IF($A36="","",_xlfn.XLOOKUP($A36,Formulas!$F:$F,Formulas!$B:$B)) -> Polar Capital Global Healthcare | C36: =IF($A36="","",_xlfn.XLOOKUP($A36,Formulas!$F:$F,Formulas!$E:$E)) -> 39.042794 | D36: =IF(OR($D35="",$D35>$D$27-1),"",$D35+1) -> 8 | E36: =IF($D36="","",_xlfn.XLOOKUP($D36,Formulas!J:J,Formulas!H:H)) -> Finsbury Growth & Income Trust | F36: =IF($D36="","",_xlfn.XLOOKUP($D36,Formulas!J:J,Formulas!I:I)) -> -139.90656 | G36: =IF(OR($G35="",$G35>$G$27-1),"",$G35+1) -> 8 | H36: =_xlfn.XLOOKUP(G36,Formulas!Q:Q,Formulas!L:L) -> Aquila European Renewables | I36: =_xlfn.XLOOKUP(G36,Formulas!Q:Q,Formulas!P:P) -> -46.8 | K36: BlackRock Throgmorton Trust | L36: Apr | M36: -189.031
A37: =IF(OR($A36="",$A36>$A$27-1),"",$A36+1) -> 9 | B37: =IF($A37="","",_xlfn.XLOOKUP($A37,Formulas!$F:$F,Formulas!$B:$B)) -> Invesco Global Equity Income Trust | C37: =IF($A37="","",_xlfn.XLOOKUP($A37,Formulas!$F:$F,Formulas!$E:$E)) -> 29.07668 | D37: =IF(OR($D36="",$D36>$D$27-1),"",$D36+1) -> 9 | E37: =IF($D37="","",_xlfn.XLOOKUP($D37,Formulas!J:J,Formulas!H:H)) -> Templeton Emerging Markets | F37: =IF($D37="","",_xlfn.XLOOKUP($D37,Formulas!J:J,Formulas!I:I)) -> -111.29841 | G37: =IF(OR($G36="",$G36>$G$27-1),"",$G36+1) -> 9 | H37: =_xlfn.XLOOKUP(G37,Formulas!Q:Q,Formulas!L:L) -> AVI Japan Opportunity Trust | I37: =_xlfn.XLOOKUP(G37,Formulas!Q:Q,Formulas!P:P) -> -46.740591 | K37: Hydrogen Capital Growth | L37: Apr | M37: -39.34
